<sdf version='1.6'>
  <world name='default'>
    <physics name='default_physics' default='0' type='ode'>
      <ode>
        <solver>
          <type>quick</type>
          <iters>20</iters>
          <sor>1</sor>
          <use_dynamic_moi_rescaling>0</use_dynamic_moi_rescaling>
        </solver>
        <constraints>
          <cfm>0</cfm>
          <erp>0.2</erp>
          <contact_max_correcting_vel>100</contact_max_correcting_vel>
          <contact_surface_layer>0</contact_surface_layer>
        </constraints>
      </ode>
      <real_time_update_rate>1000</real_time_update_rate>
      <max_step_size>0.001</max_step_size>
      <real_time_factor>1</real_time_factor>
    </physics>
    <light name='sun' type='directional'>
      <cast_shadows>1</cast_shadows>
      <pose frame=''>0 0 10 0 -0 0</pose>
      <diffuse>0.8 0.8 0.8 1</diffuse>
      <specular>0.2 0.2 0.2 1</specular>
      <attenuation>
        <range>1000</range>
        <constant>0.9</constant>
        <linear>0.01</linear>
        <quadratic>0.001</quadratic>
      </attenuation>
      <direction>-0.5 0.1 -0.9</direction>
    </light>
    <model name='ground_plane'>
      <static>1</static>
      <link name='link'>
        <collision name='collision'>
          <geometry>
            <plane>
              <normal>0 0 1</normal>
              <size>100 100</size>
            </plane>
          </geometry>
          <surface>
            <friction>
              <ode>
                <mu>100</mu>
                <mu2>50</mu2>
              </ode>
              <torsional>
                <ode/>
              </torsional>
            </friction>
            <bounce/>
            <contact>
              <ode/>
            </contact>
          </surface>
          <max_contacts>10</max_contacts>
        </collision>
        <visual name='visual'>
          <cast_shadows>0</cast_shadows>
          <geometry>
            <plane>
              <normal>0 0 1</normal>
              <size>100 100</size>
            </plane>
          </geometry>
          <material>
            <script>
              <uri>file://media/materials/scripts/gazebo.material</uri>
              <name>Gazebo/Grey</name>
            </script>
          </material>
        </visual>
        <velocity_decay>
          <linear>0</linear>
          <angular>0</angular>
        </velocity_decay>
        <self_collide>0</self_collide>
        <kinematic>0</kinematic>
        <gravity>1</gravity>
      </link>
    </model>
    <scene>
      <ambient>0.4 0.4 0.4 1</ambient>
      <background>0.7 0.7 0.7 1</background>
      <shadows>1</shadows>
    </scene>
    <spherical_coordinates>
      <surface_model>EARTH_WGS84</surface_model>
      <latitude_deg>0</latitude_deg>
      <longitude_deg>0</longitude_deg>
      <elevation>0</elevation>
      <heading_deg>0</heading_deg>
    </spherical_coordinates>
    <model name='kitchen_table'>
      <static>1</static>
      <link name='link'>
        <collision name='colision1'>
          <pose frame=''>0 0 0 0 -0 0</pose>
          <geometry>
            <mesh>
              <uri>model://kitchen_table/meshes/kitchen_table.stl</uri>
              <scale>1 1 1</scale>
            </mesh>
          </geometry>
          <surface>
            <bounce/>
            <friction>
              <ode/>
              <torsional>
                <ode/>
              </torsional>
            </friction>
            <contact>
              <ode/>
            </contact>
          </surface>
          <max_contacts>10</max_contacts>
        </collision>
        <visual name='visual1'>
          <pose frame=''>0 0 0 0 -0 0</pose>
          <geometry>
            <mesh>
              <uri>model://kitchen_table/meshes/kitchen_table.stl</uri>
              <scale>1 1 1</scale>
            </mesh>
          </geometry>
          <material>
            <script>
              <uri>file://media/materials/scripts/gazebo.material</uri>
              <name>Gazebo/FlatBlack</name>
            </script>
          </material>
        </visual>
        <velocity_decay>
          <linear>0</linear>
          <angular>0</angular>
        </velocity_decay>
        <self_collide>0</self_collide>
        <kinematic>0</kinematic>
        <gravity>1</gravity>
      </link>
      <pose frame=''>0.554544 -0.556992 0 0 -0 0</pose>
    </model>
    <state world_name='default'>
      <sim_time>871 650000000</sim_time>
      <real_time>0 0</real_time>
      <wall_time>1592432989 990862563</wall_time>
      <iterations>2</iterations>
      <model name='arm_chair'>
        <pose frame=''>4.33818 0.815613 0 0 0 -0.785398</pose>
        <scale>1 1 1</scale>
        <link name='link'>
          <pose frame=''>4.33818 0.815613 0 0 0 -0.785398</pose>
          <velocity>0 0 0 0 -0 0</velocity>
          <acceleration>0 0 0 0 -0 0</acceleration>
          <wrench>0 0 0 0 -0 0</wrench>
        </link>
      </model>
      <model name='floor_lamp'>
        <pose frame=''>4.41638 -1.15516 0.027795 0 -0 0</pose>
        <scale>1 1 1</scale>
        <link name='link'>
          <pose frame=''>4.41638 -1.15516 0.027795 0 -0 0</pose>
          <velocity>0 0 0 0 -0 0</velocity>
          <acceleration>0 0 0 0 -0 0</acceleration>
          <wrench>0 0 0 0 -0 0</wrench>
        </link>
      </model>
      <model name='ground_plane'>
        <pose frame=''>0 0 0 0 -0 0</pose>
        <scale>1 1 1</scale>
        <link name='link'>
          <pose frame=''>0 0 0 0 -0 0</pose>
          <velocity>0 0 0 0 -0 0</velocity>
          <acceleration>0 0 0 0 -0 0</acceleration>
          <wrench>0 0 0 0 -0 0</wrench>
        </link>
      </model>
      <model name='kitchen_table'>
        <pose frame=''>0.801364 -0.69646 0 0 -0 0</pose>
        <scale>1 1 1</scale>
        <link name='link'>
          <pose frame=''>0.801364 -0.69646 0 0 -0 0</pose>
          <velocity>0 0 0 0 -0 0</velocity>
          <acceleration>0 0 0 0 -0 0</acceleration>
          <wrench>0 0 0 0 -0 0</wrench>
        </link>
      </model>
      <model name='marco_titanium'>
        <pose frame=''>0 0 0.001 0 -0 0</pose>
        <scale>1 1 1</scale>
        <link name='arm_1_link'>
          <pose frame=''>0.089 0.064625 1.08477 -1e-06 1e-06 -0.2208</pose>
          <velocity>9.3e-05 -6.1e-05 -0.018598 -0.000345 0.0008 0.000315</velocity>
          <acceleration>0.057069 -0.050708 -8.84929 -1.07925 1.00248 -0.208674</acceleration>
          <wrench>0.15108 -0.13424 -23.4268 0 -0 0</wrench>
        </link>
        <link name='arm_2_link'>
          <pose frame=''>0.207401 0.044198 0.977771 1.5708 0.180002 -0.2208</pose>
          <velocity>2.9e-05 -7e-05 -0.018698 -0.00012 0.002433 0.000264</velocity>
          <acceleration>-0.125314 -0.076236 -8.88834 -1.55588 -0.0638 -3.01922</acceleration>
          <wrench>-0.198938 -0.121026 -14.1103 0 -0 0</wrench>
        </link>
        <link name='arm_3_link'>
          <pose frame=''>0.340221 0.014386 0.932672 0.545998 -1.35974 -0.776799</pose>
          <velocity>-6.5e-05 -4.4e-05 -0.019054 -0.000304 0.002309 0.000307</velocity>
          <acceleration>-0.088614 -0.017796 -9.46063 1.5308 0.039384 -1.09412</acceleration>
          <wrench>-0.159399 -0.032012 -17.0179 0 -0 0</wrench>
        </link>
        <link name='arm_4_link'>
          <pose frame=''>0.471796 -0.035518 0.905074 3.0999 -0.206956 2.56512</pose>
          <velocity>-0.000105 -1.2e-05 -0.019347 -7.9e-05 0.001402 0.000387</velocity>
          <acceleration>-0.131488 0.009305 -9.61767 1.70501 -0.862295 1.54078</acceleration>
          <wrench>-0.177608 0.012569 -12.9912 0 -0 0</wrench>
        </link>
        <link name='arm_5_link'>
          <pose frame=''>0.608368 -0.100475 0.874452 -1.78937 0.325145 -2.21811</pose>
          <velocity>-0.000113 4.3e-05 -0.01955 0.006221 -0.002876 -0.00124</velocity>
          <acceleration>-0.118648 0.060932 -9.80914 1.32294 -1.39433 1.42985</acceleration>
          <wrench>-0.157444 0.080856 -13.0165 0 -0 0</wrench>
        </link>
        <link name='arm_6_link'>
          <pose frame=''>0.731443 -0.180491 0.84363 -3.13813 0.389592 -1.60143</pose>
          <velocity>-0.000108 7.3e-05 -0.019681 0.005459 -0.013089 0.000762</velocity>
          <acceleration>-0.108845 0.076537 -9.82323 0.608225 1.44774 2.07094</acceleration>
          <wrench>-0.038946 0.027386 -3.51485 0 -0 0</wrench>
        </link>
        <link name='arm_7_link'>
          <pose frame=''>0.731443 -0.180491 0.84363 -1.56759 0.019594 -1.60268</pose>
          <velocity>-0.000108 6.3e-05 -0.019641 0.005113 -0.013684 0.000732</velocity>
          <acceleration>-0.154575 0.070793 -9.36665 2.67515 1.44228 -2.4779</acceleration>
          <wrench>-0.185681 0.085039 -11.2515 0 -0 0</wrench>
        </link>
        <link name='base_footprint'>
          <pose frame=''>0 0 0.001 0 -0 0</pose>
          <velocity>5e-06 1e-06 0 0 -0 0</velocity>
          <acceleration>0.004966 0.00103 4.9e-05 -0.000318 -9e-06 1e-06</acceleration>
          <wrench>0.179804 0.03729 0.001756 0 -0 0</wrench>
        </link>
        <link name='gripper_finger_inner_left_link'>
          <pose frame=''>0.886794 -0.16645 0.844498 -0.010094 -0.017096 1.90896</pose>
          <velocity>-0.000126 0.000143 -0.017221 -1e-05 -0.043607 -0.0008</velocity>
          <acceleration>-0.1291 0.128614 -16.4596 -2.55502 -1.17649 2.24332</acceleration>
          <wrench>-0.002582 0.002572 -0.329193 0 -0 0</wrench>
        </link>
        <link name='gripper_finger_inner_right_link'>
          <pose frame=''>0.885583 -0.204421 0.843654 -0.00407 0.019439 -1.97275</pose>
          <velocity>-8.9e-05 0.000159 -0.01742 0.004463 -0.051312 -0.000631</velocity>
          <acceleration>-0.090585 0.149088 -16.6089 1.26575 -0.252795 -1.51733</acceleration>
          <wrench>-0.001812 0.002982 -0.332177 0 -0 0</wrench>
        </link>
        <link name='gripper_finger_outer_left_link'>
          <pose frame=''>0.879748 -0.152087 0.844851 0.0091 0.017645 -1.28848</pose>
          <velocity>-0.000142 0.00012 -0.017307 0.005165 -0.017278 0.000654</velocity>
          <acceleration>-0.157203 0.136184 -16.7474 -1.92866 -1.25962 -2.26914</acceleration>
          <wrench>-0.001965 0.001702 -0.209342 0 -0 0</wrench>
        </link>
        <link name='gripper_finger_outer_right_link'>
          <pose frame=''>0.877636 -0.218309 0.843453 -3.13859 -0.019627 1.2247</pose>
          <velocity>-7.7e-05 0.000146 -0.017531 0.005063 -0.022569 0.000588</velocity>
          <acceleration>-0.063516 0.162901 -16.9885 -0.272366 -0.978448 -2.6594</acceleration>
          <wrench>-0.000794 0.002036 -0.212356 0 -0 0</wrench>
        </link>
        <link name='gripper_finger_tip_left_link'>
          <pose frame=''>0.940566 -0.14755 0.845074 3.13836 -0.01959 1.53891</pose>
          <velocity>-0.000143 9.9e-05 -0.014758 -1.5e-05 -0.042815 -0.000792</velocity>
          <acceleration>-0.144882 0.090839 -14.3251 -0.36163 -0.28018 2.39622</acceleration>
          <wrench>-0.001985 0.001244 -0.196253 0 -0 0</wrench>
        </link>
        <link name='gripper_finger_tip_right_link'>
          <pose frame=''>0.938041 -0.226717 0.843422 0.003236 0.019594 -1.60268</pose>
          <velocity>-7.7e-05 0.000128 -0.014693 0.004459 -0.051004 -0.000626</velocity>
          <acceleration>-0.077953 0.122283 -14.2054 1.83614 -0.810569 -0.960908</acceleration>
          <wrench>-0.001068 0.001675 -0.194614 0 -0 0</wrench>
        </link>
        <link name='gripper_link'>
          <pose frame=''>0.861985 -0.189865 0.843947 -3.13749 -0.019425 1.16884</pose>
          <velocity>-0.0001 0.000145 -0.017936 0.005256 -0.01341 0.00078</velocity>
          <acceleration>0.006384 0.186749 -8.12509 -1.02607 -0.841784 0.778099</acceleration>
          <wrench>2.6e-05 0.000747 -0.0325 0 -0 0</wrench>
        </link>
        <link name='head_1_link'>
          <pose frame=''>0.125 0 1.19877 1e-06 1.1e-05 -0</pose>
          <velocity>-6e-06 1.7e-05 -0.018548 0.000559 0.010993 -0.000332</velocity>
          <acceleration>0.229201 -0.000599 -8.96691 0.559054 -1.5706 -0.348707</acceleration>
          <wrench>0.022446 -5.9e-05 -0.878129 0 -0 0</wrench>
        </link>
        <link name='head_2_link'>
          <pose frame=''>0.1605 0 1.22177 1.5708 0.380011 0</pose>
          <velocity>0.00023 0 -0.01882 0.000305 0.010909 -0.000102</velocity>
          <acceleration>0.041951 0.000949 -9.49855 1.29607 0.410227 -2.80623</acceleration>
          <wrench>0.019861 0.000449 -4.49709 0 -0 0</wrench>
        </link>
        <link name='torso_lift_link'>
          <pose frame=''>-0.068 0 1.08777 0 1e-06 0</pose>
          <velocity>-8.3e-05 -4.7e-05 -0.01849 -0.000211 0.000741 -0.000322</velocity>
          <acceleration>0.10048 0.006893 -8.67928 -0.211293 0.742123 -0.318682</acceleration>
          <wrench>0.663271 0.0455 -57.292 0 -0 0</wrench>
        </link>
        <link name='wheel_left_link'>
          <pose frame=''>0 0.2022 0.0995 -1.5708 0 0</pose>
          <velocity>5e-06 1e-06 0 0 -0 0</velocity>
          <acceleration>0.005391 0.001027 -1e-05 -0.000323 -2e-06 3.1e-05</acceleration>
          <wrench>0.009832 0.001873 -1.8e-05 0 -0 0</wrench>
        </link>
        <link name='wheel_right_link'>
          <pose frame=''>0 -0.2022 0.0995 -1.5708 0 0</pose>
          <velocity>5e-06 1e-06 0 0 -0 0</velocity>
          <acceleration>0.005421 0.001022 0.00013 -0.000363 -2e-06 0.000455</acceleration>
          <wrench>0.009887 0.001863 0.000237 0 -0 0</wrench>
        </link>
      </model>
      <model name='microwave_oven'>
        <pose frame=''>1.175 -0.075611 0.674992 1.9e-05 -4.5e-05 -1.57069</pose>
        <scale>1 1 1</scale>
        <link name='base_link'>
          <pose frame=''>1.175 -0.075611 0.674992 1.9e-05 -4.5e-05 -1.57069</pose>
          <velocity>-0.000982 0.000305 -0.007675 -0.044501 -0.019103 0.004812</velocity>
          <acceleration>-0.79279 0.571613 -6.42672 2.30091 0.059742 0.652944</acceleration>
          <wrench>-8.47493 6.11054 -68.7016 0 -0 0</wrench>
        </link>
        <link name='door_link'>
          <pose frame=''>1.03849 0.135875 0.677111 1.57082 -4.4e-05 -1.57773</pose>
          <velocity>-0.001972 -0.000435 -0.019817 -0.044651 -0.018898 0.004841</velocity>
          <acceleration>-0.706303 1.27113 -8.55358 1.81084 -1.16385 -2.81417</acceleration>
          <wrench>-0.788941 1.41985 -9.55435 0 -0 0</wrench>
        </link>
      </model>
      <model name='sideboard'>
        <pose frame=''>2.86888 -0.511468 0 0 -0 0</pose>
        <scale>1 1 1</scale>
        <link name='link'>
          <pose frame=''>2.86888 -0.511468 0 0 -0 0</pose>
          <velocity>0 0 0 0 -0 0</velocity>
          <acceleration>0 0 0 0 -0 0</acceleration>
          <wrench>0 0 0 0 -0 0</wrench>
        </link>
      </model>
      <model name='sofa'>
        <pose frame=''>2.45572 1.07511 0 0 -0 0</pose>
        <scale>1 1 1</scale>
        <link name='link'>
          <pose frame=''>2.45572 1.07511 0 0 -0 0</pose>
          <velocity>0 0 0 0 -0 0</velocity>
          <acceleration>0 0 0 0 -0 0</acceleration>
          <wrench>0 0 0 0 -0 0</wrench>
        </link>
      </model>
      <model name='tv'>
        <pose frame=''>2.86662 -0.344549 0.696618 0 -0 0</pose>
        <scale>1 1 1</scale>
        <link name='link'>
          <pose frame=''>2.86662 -0.344549 0.696618 0 -0 0</pose>
          <velocity>0 0 0 0 -0 0</velocity>
          <acceleration>0 0 0 0 -0 0</acceleration>
          <wrench>0 0 0 0 -0 0</wrench>
        </link>
      </model>
      <light name='sun'>
        <pose frame=''>0 0 10 0 -0 0</pose>
      </light>
    </state>
    <gui fullscreen='0'>
      <camera name='user_camera'>
        <pose frame=''>0.973695 -0.104358 2.08093 0 1.43964 0.016989</pose>
        <view_controller>orbit</view_controller>
        <projection_type>perspective</projection_type>
      </camera>
    </gui>
    <gravity>0 0 -9.81</gravity>
    <magnetic_field>6e-06 2.3e-05 -4.2e-05</magnetic_field>
    <atmosphere type='adiabatic'/>
    <model name='microwave_oven'>
      <link name='base_link'>
        <pose frame=''>0 0 0 0 -0 0</pose>
        <inertial>
          <pose frame=''>-0.003499 0.0063 0.095793 0 -0 0</pose>
          <mass>10.69</mass>
          <inertia>
            <ixx>0.15798</ixx>
            <ixy>0.002699</ixy>
            <ixz>0.0025714</ixz>
            <iyy>0.31998</iyy>
            <iyz>-0.0019679</iyz>
            <izz>0.30475</izz>
          </inertia>
        </inertial>
        <collision name='base_link_collision'>
          <pose frame=''>0 0 0 0 -0 0</pose>
          <geometry>
            <mesh>
              <scale>1 1 1</scale>
              <uri>model://microwave_oven/meshes/base_link.STL</uri>
            </mesh>
          </geometry>
          <max_contacts>10</max_contacts>
          <surface>
            <contact>
              <ode/>
            </contact>
            <bounce/>
            <friction>
              <torsional>
                <ode/>
              </torsional>
              <ode/>
            </friction>
          </surface>
        </collision>
        <visual name='base_link_visual'>
          <pose frame=''>0 0 0 0 -0 0</pose>
          <geometry>
            <mesh>
              <scale>1 1 1</scale>
              <uri>model://microwave_oven/meshes/base_link.STL</uri>
            </mesh>
          </geometry>
        </visual>
        <self_collide>0</self_collide>
        <kinematic>0</kinematic>
        <gravity>1</gravity>
      </link>
      <link name='door_link'>
        <pose frame=''>-0.2115 -0.13648 0.002131 1.5708 -0 0</pose>
        <inertial>
          <pose frame=''>0.18216 0.11795 0.017746 0 -0 0</pose>
          <mass>1.117</mass>
          <inertia>
            <ixx>0.0067183</ixx>
            <ixy>-1.793e-07</ixy>
            <ixz>-0.00018641</ixz>
            <iyy>0.015795</iyy>
            <iyz>-8.4864e-08</iyz>
            <izz>0.022237</izz>
          </inertia>
        </inertial>
        <collision name='door_link_collision'>
          <pose frame=''>0 0 0 0 -0 0</pose>
          <geometry>
            <mesh>
              <scale>1 1 1</scale>
              <uri>model://microwave_oven/meshes/door_link.STL</uri>
            </mesh>
          </geometry>
          <max_contacts>10</max_contacts>
          <surface>
            <contact>
              <ode/>
            </contact>
            <bounce/>
            <friction>
              <torsional>
                <ode/>
              </torsional>
              <ode/>
            </friction>
          </surface>
        </collision>
        <visual name='door_link_visual'>
          <pose frame=''>0 0 0 0 -0 0</pose>
          <geometry>
            <mesh>
              <scale>1 1 1</scale>
              <uri>model://microwave_oven/meshes/door_link.STL</uri>
            </mesh>
          </geometry>
        </visual>
        <self_collide>0</self_collide>
        <kinematic>0</kinematic>
        <gravity>1</gravity>
      </link>
      <joint name='door_joint' type='revolute'>
        <child>door_link</child>
        <parent>base_link</parent>
        <axis>
          <xyz>0 0 1</xyz>
          <limit>
            <lower>-1.5708</lower>
            <upper>0</upper>
            <effort>30</effort>
            <velocity>1</velocity>
          </limit>
          <dynamics>
            <damping>0.5</damping>
            <friction>5</friction>
            <spring_reference>0</spring_reference>
            <spring_stiffness>0</spring_stiffness>
          </dynamics>
          <use_parent_model_frame>1</use_parent_model_frame>
        </axis>
      </joint>
      <pose frame=''>0.564832 -0.041945 0 0 -0 0</pose>
    </model>
    <model name='arm_chair'>
      <static>1</static>
      <link name='link'>
        <collision name='colision1'>
          <pose frame=''>0 0 0 0 -0 0</pose>
          <geometry>
            <mesh>
              <uri>model://arm_chair/meshes/arm_chair.stl</uri>
              <scale>1 1 1</scale>
            </mesh>
          </geometry>
          <surface>
            <bounce/>
            <friction>
              <ode/>
              <torsional>
                <ode/>
              </torsional>
            </friction>
            <contact>
              <ode/>
            </contact>
          </surface>
          <max_contacts>10</max_contacts>
        </collision>
        <visual name='visual1'>
          <pose frame=''>0 0 0 0 -0 0</pose>
          <geometry>
            <mesh>
              <uri>model://arm_chair/meshes/arm_chair.stl</uri>
              <scale>1 1 1</scale>
            </mesh>
          </geometry>
          <material>
            <script>
              <uri>file://media/materials/scripts/gazebo.material</uri>
              <name>Gazebo/PaintedWall</name>
            </script>
          </material>
        </visual>
        <velocity_decay>
          <linear>0</linear>
          <angular>0</angular>
        </velocity_decay>
        <self_collide>0</self_collide>
        <kinematic>0</kinematic>
        <gravity>1</gravity>
      </link>
      <pose frame=''>0.947248 0.967277 0 0 -0 0</pose>
    </model>
    <model name='floor_lamp'>
      <static>1</static>
      <link name='link'>
        <collision name='colision1'>
          <pose frame=''>0 0 0 0 -0 0</pose>
          <geometry>
            <mesh>
              <uri>model://floor_lamp/meshes/floor_lamp.stl</uri>
              <scale>1 1 1</scale>
            </mesh>
          </geometry>
          <surface>
            <bounce/>
            <friction>
              <ode/>
              <torsional>
                <ode/>
              </torsional>
            </friction>
            <contact>
              <ode/>
            </contact>
          </surface>
          <max_contacts>10</max_contacts>
        </collision>
        <visual name='visual1'>
          <pose frame=''>0 0 0 0 -0 0</pose>
          <geometry>
            <mesh>
              <uri>model://floor_lamp/meshes/floor_lamp.stl</uri>
              <scale>1 1 1</scale>
            </mesh>
          </geometry>
          <material>
            <script>
              <uri>file://media/materials/scripts/gazebo.material</uri>
              <name>Gazebo/Grey</name>
            </script>
          </material>
        </visual>
        <velocity_decay>
          <linear>0</linear>
          <angular>0</angular>
        </velocity_decay>
        <self_collide>0</self_collide>
        <kinematic>0</kinematic>
        <gravity>1</gravity>
      </link>
      <pose frame=''>3.00429 -1.1527 0 0 -0 0</pose>
    </model>
    <model name='sofa'>
      <static>1</static>
      <link name='link'>
        <collision name='colision1'>
          <pose frame=''>0 0 0 0 -0 0</pose>
          <geometry>
            <mesh>
              <uri>model://sofa/meshes/sofa.stl</uri>
              <scale>1 1 1</scale>
            </mesh>
          </geometry>
          <surface>
            <bounce/>
            <friction>
              <ode/>
              <torsional>
                <ode/>
              </torsional>
            </friction>
            <contact>
              <ode/>
            </contact>
          </surface>
          <max_contacts>10</max_contacts>
        </collision>
        <visual name='visual1'>
          <pose frame=''>0 0 0 0 -0 0</pose>
          <geometry>
            <mesh>
              <uri>model://sofa/meshes/sofa.stl</uri>
              <scale>1 1 1</scale>
            </mesh>
          </geometry>
          <material>
            <script>
              <uri>file://media/materials/scripts/gazebo.material</uri>
              <name>Gazebo/PaintedWall</name>
            </script>
          </material>
        </visual>
        <velocity_decay>
          <linear>0</linear>
          <angular>0</angular>
        </velocity_decay>
        <self_collide>0</self_collide>
        <kinematic>0</kinematic>
        <gravity>1</gravity>
      </link>
      <pose frame=''>2.558 1.15364 0 0 -0 0</pose>
    </model>
    <model name='sideboard'>
      <static>1</static>
      <link name='link'>
        <collision name='colision1'>
          <pose frame=''>0 0 0 0 -0 0</pose>
          <geometry>
            <mesh>
              <uri>model://sideboard/meshes/sideboard.stl</uri>
              <scale>1 1 1</scale>
            </mesh>
          </geometry>
          <surface>
            <bounce/>
            <friction>
              <ode/>
              <torsional>
                <ode/>
              </torsional>
            </friction>
            <contact>
              <ode/>
            </contact>
          </surface>
          <max_contacts>10</max_contacts>
        </collision>
        <visual name='visual1'>
          <pose frame=''>0 0 0 0 -0 0</pose>
          <geometry>
            <mesh>
              <uri>model://sideboard/meshes/sideboard.stl</uri>
              <scale>1 1 1</scale>
            </mesh>
          </geometry>
          <material>
            <script>
              <uri>file://media/materials/scripts/gazebo.material</uri>
              <name>Gazebo/FlatBlack</name>
            </script>
          </material>
        </visual>
        <velocity_decay>
          <linear>0</linear>
          <angular>0</angular>
        </velocity_decay>
        <self_collide>0</self_collide>
        <kinematic>0</kinematic>
        <gravity>1</gravity>
      </link>
      <pose frame=''>2.86888 -0.511468 0 0 -0 0</pose>
    </model>
    <model name='tv'>
      <static>1</static>
      <link name='link'>
        <collision name='colision1'>
          <pose frame=''>0 0 0 0 -0 0</pose>
          <geometry>
            <mesh>
              <uri>model://tv/meshes/tv.stl</uri>
              <scale>1 1 1</scale>
            </mesh>
          </geometry>
          <surface>
            <bounce/>
            <friction>
              <ode/>
              <torsional>
                <ode/>
              </torsional>
            </friction>
            <contact>
              <ode/>
            </contact>
          </surface>
          <max_contacts>10</max_contacts>
        </collision>
        <visual name='visual1'>
          <pose frame=''>0 0 0 0 -0 0</pose>
          <geometry>
            <mesh>
              <uri>model://tv/meshes/tv.stl</uri>
              <scale>1 1 1</scale>
            </mesh>
          </geometry>
          <material>
            <script>
              <uri>file://media/materials/scripts/gazebo.material</uri>
              <name>Gazebo/Black</name>
            </script>
          </material>
        </visual>
        <velocity_decay>
          <linear>0</linear>
          <angular>0</angular>
        </velocity_decay>
        <self_collide>0</self_collide>
        <kinematic>0</kinematic>
        <gravity>1</gravity>
      </link>
      <pose frame=''>4.38291 0.644591 0 0 -0 0</pose>
    </model>
    <model name='marco_titanium'>
      <link name='base_footprint'>
        <pose frame=''>0 0 0 0 -0 0</pose>
        <inertial>
          <pose frame=''>-0.003349 0.005545 0.225114 0 -0 0</pose>
          <mass>36.2063</mass>
          <inertia>
            <ixx>1.15405</ixx>
            <ixy>-0.000980851</ixy>
            <ixz>0.152833</ixz>
            <iyy>1.18492</iyy>
            <iyz>0.0119227</iyz>
            <izz>0.616676</izz>
          </inertia>
        </inertial>
        <collision name='base_footprint_fixed_joint_lump__base_link_collision'>
          <pose frame=''>0 0 0.0985 0 -0 0</pose>
          <geometry>
            <mesh>
              <scale>1 1 1</scale>
              <uri>/home/jasper/omni_marco_gazebo/src/robot_models/marco/ant_description/meshes/base/base_collision.dae</uri>
            </mesh>
          </geometry>
          <surface>
            <contact>
              <ode/>
            </contact>
            <friction>
              <ode/>
              <torsional>
                <ode/>
              </torsional>
            </friction>
            <bounce/>
          </surface>
          <max_contacts>10</max_contacts>
        </collision>
        <collision name='base_footprint_fixed_joint_lump__torso_fixed_link_collision_1'>
          <pose frame=''>-0.068 0 0.2885 0 -0 0</pose>
          <geometry>
            <mesh>
              <scale>1 1 1</scale>
              <uri>/home/jasper/omni_marco_gazebo/src/robot_models/marco/marco_description/meshes/torso/lifting_column_inner_body2.stl</uri>
            </mesh>
          </geometry>
          <max_contacts>10</max_contacts>
          <surface>
            <contact>
              <ode/>
            </contact>
            <bounce/>
            <friction>
              <torsional>
                <ode/>
              </torsional>
              <ode/>
            </friction>
          </surface>
        </collision>
        <collision name='base_footprint_fixed_joint_lump__torso_fixed_link_collision_2'>
          <pose frame=''>0 0 0.1685 0 -0 0</pose>
          <geometry>
            <cylinder>
              <length>0.104</length>
              <radius>0.24</radius>
            </cylinder>
          </geometry>
          <max_contacts>10</max_contacts>
          <surface>
            <contact>
              <ode/>
            </contact>
            <bounce/>
            <friction>
              <torsional>
                <ode/>
              </torsional>
              <ode/>
            </friction>
          </surface>
        </collision>
        <visual name='base_footprint_fixed_joint_lump__base_link_visual'>
          <pose frame=''>0 0 0.0985 0 -0 0</pose>
          <geometry>
            <mesh>
              <scale>1 1 1</scale>
              <uri>/home/jasper/omni_marco_gazebo/src/robot_models/marco/ant_description/meshes/base/base.stl</uri>
            </mesh>
          </geometry>
          <material>
            <script>
              <name>Gazebo/DarkGrey</name>
              <uri>file://media/materials/scripts/gazebo.material</uri>
            </script>
          </material>
        </visual>
        <visual name='base_footprint_fixed_joint_lump__base_laser_link_visual_1'>
          <pose frame=''>0.185 0 0.1085 0 -0 0</pose>
          <geometry>
            <mesh>
              <scale>1 1 1</scale>
              <uri>/home/jasper/omni_marco_gazebo/src/robot_models/marco/ant_description/meshes/sensors/hokuyo_urg_04lx_ug01.stl</uri>
            </mesh>
          </geometry>
          <material>
            <script>
              <uri>__default__</uri>
              <name>__default__</name>
            </script>
          </material>
        </visual>
        <visual name='base_footprint_fixed_joint_lump__caster_back_left_1_link_visual_2'>
          <pose frame=''>-0.1715 0.102 0.0585 0 -0 0</pose>
          <geometry>
            <mesh>
              <scale>1 1 1</scale>
              <uri>/home/jasper/omni_marco_gazebo/src/robot_models/marco/ant_description/meshes/wheels/caster_1.stl</uri>
            </mesh>
          </geometry>
        </visual>
        <visual name='base_footprint_fixed_joint_lump__caster_back_left_2_link_visual_3'>
          <pose frame=''>-0.1885 0.1023 0.0265 -1.5708 0 0</pose>
          <geometry>
            <mesh>
              <scale>1 1 1</scale>
              <uri>/home/jasper/omni_marco_gazebo/src/robot_models/marco/ant_description/meshes/wheels/caster_2.stl</uri>
            </mesh>
          </geometry>
        </visual>
        <visual name='base_footprint_fixed_joint_lump__caster_back_right_1_link_visual_4'>
          <pose frame=''>-0.1715 -0.102 0.0585 0 -0 0</pose>
          <geometry>
            <mesh>
              <scale>1 1 1</scale>
              <uri>/home/jasper/omni_marco_gazebo/src/robot_models/marco/ant_description/meshes/wheels/caster_1.stl</uri>
            </mesh>
          </geometry>
        </visual>
        <visual name='base_footprint_fixed_joint_lump__caster_back_right_2_link_visual_5'>
          <pose frame=''>-0.1885 -0.1017 0.0265 -1.5708 0 0</pose>
          <geometry>
            <mesh>
              <scale>1 1 1</scale>
              <uri>/home/jasper/omni_marco_gazebo/src/robot_models/marco/ant_description/meshes/wheels/caster_2.stl</uri>
            </mesh>
          </geometry>
        </visual>
        <visual name='base_footprint_fixed_joint_lump__caster_front_left_1_link_visual_6'>
          <pose frame=''>0.1715 0.102 0.0585 0 -0 0</pose>
          <geometry>
            <mesh>
              <scale>1 1 1</scale>
              <uri>/home/jasper/omni_marco_gazebo/src/robot_models/marco/ant_description/meshes/wheels/caster_1.stl</uri>
            </mesh>
          </geometry>
        </visual>
        <visual name='base_footprint_fixed_joint_lump__caster_front_left_2_link_visual_7'>
          <pose frame=''>0.1545 0.1023 0.0265 -1.5708 0 0</pose>
          <geometry>
            <mesh>
              <scale>1 1 1</scale>
              <uri>/home/jasper/omni_marco_gazebo/src/robot_models/marco/ant_description/meshes/wheels/caster_2.stl</uri>
            </mesh>
          </geometry>
        </visual>
        <visual name='base_footprint_fixed_joint_lump__caster_front_right_1_link_visual_8'>
          <pose frame=''>0.1715 -0.102 0.0585 0 -0 0</pose>
          <geometry>
            <mesh>
              <scale>1 1 1</scale>
              <uri>/home/jasper/omni_marco_gazebo/src/robot_models/marco/ant_description/meshes/wheels/caster_1.stl</uri>
            </mesh>
          </geometry>
        </visual>
        <visual name='base_footprint_fixed_joint_lump__caster_front_right_2_link_visual_9'>
          <pose frame=''>0.1545 -0.1017 0.0265 -1.5708 0 0</pose>
          <geometry>
            <mesh>
              <scale>1 1 1</scale>
              <uri>/home/jasper/omni_marco_gazebo/src/robot_models/marco/ant_description/meshes/wheels/caster_2.stl</uri>
            </mesh>
          </geometry>
        </visual>
        <visual name='base_footprint_fixed_joint_lump__torso_fixed_link_visual_10'>
          <pose frame=''>-0.068 0 0.2885 0 -0 0</pose>
          <geometry>
            <mesh>
              <scale>1 1 1</scale>
              <uri>/home/jasper/omni_marco_gazebo/src/robot_models/marco/marco_description/meshes/torso/lifting_column_inner_body2.stl</uri>
            </mesh>
          </geometry>
        </visual>
        <visual name='base_footprint_fixed_joint_lump__torso_fixed_link_visual_11'>
          <pose frame=''>0 0 0.3405 0 -0 0</pose>
          <geometry>
            <cylinder>
              <length>0.104</length>
              <radius>0.24</radius>
            </cylinder>
          </geometry>
        </visual>
        <velocity_decay/>
        <velocity_decay/>
        <gravity>1</gravity>
        <velocity_decay/>
        <self_collide>0</self_collide>
        <sensor name='base_laser' type='ray'>
          <update_rate>10</update_rate>
          <visualize>1</visualize>
          <ray>
            <scan>
              <horizontal>
                <samples>626</samples>
                <resolution>1</resolution>
                <min_angle>-1.91986</min_angle>
                <max_angle>1.91986</max_angle>
              </horizontal>
              <vertical>
                <samples>1</samples>
                <min_angle>0</min_angle>
                <max_angle>0</max_angle>
              </vertical>
            </scan>
            <range>
              <min>0.02</min>
              <max>5.6</max>
              <resolution>0.001</resolution>
            </range>
          </ray>
          <plugin name='gazebo_ros_hokuyo_laser' filename='libgazebo_ros_laser.so'>
            <gaussianNoise>0.03</gaussianNoise>
            <alwaysOn>true</alwaysOn>
            <updateRate>10</updateRate>
            <topicName>scan</topicName>
            <frameName>base_laser_link</frameName>
            <robotNamespace>/</robotNamespace>
          </plugin>
          <pose frame=''>0.185 0 0.1085 0 -0 0</pose>
        </sensor>
        <kinematic>0</kinematic>
      </link>
      <joint name='world_to_base_footprint' type='revolute'>
        <child>base_footprint</child>
        <parent>world</parent>
        <axis>
          <limit>
            <lower>0</lower>
            <upper>0</upper>
          </limit>
          <dynamics>
            <damping>0</damping>
            <friction>0</friction>
            <spring_reference>0</spring_reference>
            <spring_stiffness>0</spring_stiffness>
          </dynamics>
          <use_parent_model_frame>1</use_parent_model_frame>
          <xyz>0 0 1</xyz>
        </axis>
      </joint>
      <link name='torso_lift_link'>
        <pose frame=''>-0.068 0 0.7868 0 -0 0</pose>
        <inertial>
          <pose frame=''>-0.000485 0 0.248476 0 -0 0</pose>
          <mass>6.60101</mass>
          <inertia>
            <ixx>0.0211832</ixx>
            <ixy>0</ixy>
            <ixz>-0.000650619</ixz>
            <iyy>0.0233717</iyy>
            <iyz>0</iyz>
            <izz>0.004471</izz>
          </inertia>
        </inertial>
        <collision name='torso_lift_link_collision'>
          <pose frame=''>0 0 -0.474 0 -0 0</pose>
          <geometry>
            <mesh>
              <scale>1 1 1</scale>
              <uri>/home/jasper/omni_marco_gazebo/src/robot_models/marco/marco_description/meshes/torso/lifting_column_moving_link.stl</uri>
            </mesh>
          </geometry>
          <max_contacts>10</max_contacts>
          <surface>
            <contact>
              <ode/>
            </contact>
            <bounce/>
            <friction>
              <torsional>
                <ode/>
              </torsional>
              <ode/>
            </friction>
          </surface>
        </collision>
        <collision name='torso_lift_link_collision_1'>
          <pose frame=''>0.187 0 0.02 0 -0 0</pose>
          <geometry>
            <box>
              <size>0.06 0.04 0.04</size>
            </box>
          </geometry>
          <max_contacts>10</max_contacts>
          <surface>
            <contact>
              <ode/>
            </contact>
            <bounce/>
            <friction>
              <torsional>
                <ode/>
              </torsional>
              <ode/>
            </friction>
          </surface>
        </collision>
        <collision name='torso_lift_link_fixed_joint_lump__laptop_tray_fixed_link_collision_2'>
          <pose frame=''>-0.03 0 0.05 0 -0 0</pose>
          <geometry>
            <box>
              <size>0.265 0.33 0.1</size>
            </box>
          </geometry>
          <max_contacts>10</max_contacts>
          <surface>
            <contact>
              <ode/>
            </contact>
            <bounce/>
            <friction>
              <torsional>
                <ode/>
              </torsional>
              <ode/>
            </friction>
          </surface>
        </collision>
        <collision name='torso_lift_link_fixed_joint_lump__rear_cam_link_collision_3'>
          <pose frame=''>-0.2 0 0 0 -0 0</pose>
          <geometry>
            <cylinder>
              <length>0.04</length>
              <radius>0.014</radius>
            </cylinder>
          </geometry>
          <max_contacts>10</max_contacts>
          <surface>
            <contact>
              <ode/>
            </contact>
            <bounce/>
            <friction>
              <torsional>
                <ode/>
              </torsional>
              <ode/>
            </friction>
          </surface>
        </collision>
        <visual name='torso_lift_link_visual'>
          <pose frame=''>0 0 -0.474 0 -0 0</pose>
          <geometry>
            <mesh>
              <scale>1 1 1</scale>
              <uri>/home/jasper/omni_marco_gazebo/src/robot_models/marco/marco_description/meshes/torso/lifting_column_moving_link.stl</uri>
            </mesh>
          </geometry>
        </visual>
        <visual name='torso_lift_link_visual_1'>
          <pose frame=''>0.187 0 0.02 0 -0 0</pose>
          <geometry>
            <box>
              <size>0.06 0.04 0.04</size>
            </box>
          </geometry>
        </visual>
        <visual name='torso_lift_link_fixed_joint_lump__laptop_tray_fixed_link_visual_2'>
          <pose frame=''>-0.03 0 0.05 0 -0 0</pose>
          <geometry>
            <box>
              <size>0.265 0.33 0.1</size>
            </box>
          </geometry>
        </visual>
        <visual name='torso_lift_link_fixed_joint_lump__rear_cam_link_visual_3'>
          <pose frame=''>-0.2 0 0 0 -0 0</pose>
          <geometry>
            <cylinder>
              <length>0.04</length>
              <radius>0.014</radius>
            </cylinder>
          </geometry>
        </visual>
        <gravity>1</gravity>
        <velocity_decay/>
        <self_collide>0</self_collide>
        <sensor name='rear_cam' type='camera'>
          <update_rate>30</update_rate>
          <camera name='rear_cam'>
            <horizontal_fov>1.39626</horizontal_fov>
            <image>
              <width>1280</width>
              <height>720</height>
              <format>R8G8B8</format>
            </image>
            <clip>
              <near>0.02</near>
              <far>300</far>
            </clip>
            <noise>
              <type>gaussian</type>
              <mean>0</mean>
              <stddev>0.007</stddev>
            </noise>
          </camera>
          <plugin name='camera_controller' filename='libgazebo_ros_camera.so'>
            <alwaysOn>true</alwaysOn>
            <updateRate>0.0</updateRate>
            <cameraName>rear_cam</cameraName>
            <imageTopicName>image_raw</imageTopicName>
            <cameraInfoTopicName>camera_info</cameraInfoTopicName>
            <frameName>rear_cam_optical_frame</frameName>
            <hackBaseline>0.0</hackBaseline>
            <distortionK1>0.0</distortionK1>
            <distortionK2>0.0</distortionK2>
            <distortionK3>0.0</distortionK3>
            <distortionT1>0.0</distortionT1>
            <distortionT2>0.0</distortionT2>
            <CxPrime>0</CxPrime>
            <Cx>0.0</Cx>
            <Cy>0.0</Cy>
            <focalLength>0.0</focalLength>
            <robotNamespace>/</robotNamespace>
          </plugin>
          <pose frame=''>-0.2 0 -0.025 3.14159 1.57079 -3.14159</pose>
        </sensor>
        <kinematic>0</kinematic>
      </link>
      <joint name='torso_lift_joint' type='prismatic'>
        <child>torso_lift_link</child>
        <parent>base_footprint</parent>
        <axis>
          <xyz>0 0 1</xyz>
          <limit>
            <lower>0.09</lower>
            <upper>0.35</upper>
            <effort>2000</effort>
            <velocity>0.05</velocity>
          </limit>
          <dynamics>
            <damping>1000</damping>
            <friction>0</friction>
            <spring_reference>0</spring_reference>
            <spring_stiffness>0</spring_stiffness>
          </dynamics>
          <use_parent_model_frame>1</use_parent_model_frame>
        </axis>
      </joint>
      <link name='arm_1_link'>
        <pose frame=''>0.089 0.064625 0.7838 0 0 -1.5708</pose>
        <inertial>
          <pose frame=''>0.08375 0.00308 -0.04965 0 -0 0</pose>
          <mass>2.64731</mass>
          <inertia>
            <ixx>0.0148882</ixx>
            <ixy>0.00097928</ixy>
            <ixz>-0.0145994</ixz>
            <iyy>0.0378581</iyy>
            <iyz>-0.000866362</iyz>
            <izz>0.026172</izz>
          </inertia>
        </inertial>
        <collision name='arm_1_link_collision'>
          <pose frame=''>0 0 -0.0425 0 -0 0</pose>
          <geometry>
            <cylinder>
              <length>0.085</length>
              <radius>0.045</radius>
            </cylinder>
          </geometry>
          <surface>
            <contact>
              <ode/>
            </contact>
            <friction>
              <ode>
                <mu>0.9</mu>
                <mu2>0.9</mu2>
              </ode>
              <torsional>
                <ode/>
              </torsional>
            </friction>
            <bounce/>
          </surface>
          <max_contacts>10</max_contacts>
        </collision>
        <collision name='arm_1_link_collision_1'>
          <pose frame=''>0 0 -0.0425 0 -0 0</pose>
          <geometry>
            <cylinder>
              <length>0.02</length>
              <radius>0.045</radius>
            </cylinder>
          </geometry>
          <surface>
            <contact>
              <ode/>
            </contact>
            <friction>
              <ode>
                <mu>0.9</mu>
                <mu2>0.9</mu2>
              </ode>
              <torsional>
                <ode/>
              </torsional>
            </friction>
            <bounce/>
          </surface>
          <max_contacts>10</max_contacts>
        </collision>
        <collision name='arm_1_link_collision_2'>
          <pose frame=''>0.12 0 -0.107 -1.5708 -0 -3.14159</pose>
          <geometry>
            <mesh>
              <scale>1 1 1</scale>
              <uri>/home/jasper/omni_marco_gazebo/src/robot_models/marco/marco_description/meshes/arm/arm_2_collision.stl</uri>
            </mesh>
          </geometry>
          <surface>
            <contact>
              <ode/>
            </contact>
            <friction>
              <ode>
                <mu>0.9</mu>
                <mu2>0.9</mu2>
              </ode>
              <torsional>
                <ode/>
              </torsional>
            </friction>
            <bounce/>
          </surface>
          <max_contacts>10</max_contacts>
        </collision>
        <visual name='arm_1_link_visual'>
          <pose frame=''>0 0 -0.0425 0 -0 0</pose>
          <geometry>
            <cylinder>
              <length>0.085</length>
              <radius>0.045</radius>
            </cylinder>
          </geometry>
          <material>
            <script>
              <name>Gazebo/DarkGrey</name>
              <uri>file://media/materials/scripts/gazebo.material</uri>
            </script>
          </material>
        </visual>
        <visual name='arm_1_link_visual_1'>
          <pose frame=''>0.05 0 0.01 0 -0 0</pose>
          <geometry>
            <box>
              <size>0.2 0.09 0.02</size>
            </box>
          </geometry>
          <material>
            <script>
              <name>Gazebo/DarkGrey</name>
              <uri>file://media/materials/scripts/gazebo.material</uri>
            </script>
          </material>
        </visual>
        <visual name='arm_1_link_visual_2'>
          <pose frame=''>0.12 0 -0.107 -1.5708 -0 -3.14159</pose>
          <geometry>
            <mesh>
              <scale>1 1 1</scale>
              <uri>/home/jasper/omni_marco_gazebo/src/robot_models/marco/marco_description/meshes/arm/arm_2.dae</uri>
            </mesh>
          </geometry>
          <material>
            <script>
              <name>Gazebo/DarkGrey</name>
              <uri>file://media/materials/scripts/gazebo.material</uri>
            </script>
          </material>
        </visual>
        <gravity>1</gravity>
        <velocity_decay/>
        <self_collide>0</self_collide>
        <kinematic>0</kinematic>
      </link>
      <joint name='arm_1_joint' type='revolute'>
        <child>arm_1_link</child>
        <parent>torso_lift_link</parent>
        <axis>
          <xyz>0 0 1</xyz>
          <limit>
            <lower>0</lower>
            <upper>3.14159</upper>
            <effort>39</effort>
            <velocity>2.7</velocity>
          </limit>
          <dynamics>
            <damping>1</damping>
            <friction>1</friction>
            <spring_reference>0</spring_reference>
            <spring_stiffness>0</spring_stiffness>
          </dynamics>
          <use_parent_model_frame>1</use_parent_model_frame>
        </axis>
        <physics>
          <ode>
            <implicit_spring_damper>1</implicit_spring_damper>
            <cfm_damping>1</cfm_damping>
            <limit>
              <cfm>0</cfm>
              <erp>0.2</erp>
            </limit>
          </ode>
        </physics>
      </joint>
      <link name='arm_2_link'>
        <pose frame=''>0.095 -0.055375 0.6768 1.5708 0 -1.5708</pose>
        <inertial>
          <pose frame=''>0.01435 -0.06294 0.01039 0 -0 0</pose>
          <mass>1.58751</mass>
          <inertia>
            <ixx>0.00225337</ixx>
            <ixy>-0.00185617</ixy>
            <ixz>0.000230944</ixz>
            <iyy>0.010792</iyy>
            <iyz>-4.74125e-05</iyz>
            <izz>0.0112248</izz>
          </inertia>
        </inertial>
        <collision name='arm_2_link_collision'>
          <pose frame=''>0 0 0 -3.14159 -0 -1.5708</pose>
          <geometry>
            <mesh>
              <scale>1 1 1</scale>
              <uri>/home/jasper/omni_marco_gazebo/src/robot_models/marco/marco_description/meshes/arm/arm_2_collision.stl</uri>
            </mesh>
          </geometry>
          <surface>
            <contact>
              <ode/>
            </contact>
            <friction>
              <ode>
                <mu>0.9</mu>
                <mu2>0.9</mu2>
              </ode>
              <torsional>
                <ode/>
              </torsional>
            </friction>
            <bounce/>
          </surface>
          <max_contacts>10</max_contacts>
        </collision>
        <visual name='arm_2_link_visual'>
          <pose frame=''>0 0 0 -3.14159 -0 -1.5708</pose>
          <geometry>
            <mesh>
              <scale>1 1 1</scale>
              <uri>/home/jasper/omni_marco_gazebo/src/robot_models/marco/marco_description/meshes/arm/arm_2.dae</uri>
            </mesh>
          </geometry>
          <material>
            <script>
              <name>Gazebo/DarkGrey</name>
              <uri>file://media/materials/scripts/gazebo.material</uri>
            </script>
          </material>
        </visual>
        <gravity>1</gravity>
        <velocity_decay/>
        <self_collide>0</self_collide>
        <kinematic>0</kinematic>
      </link>
      <joint name='arm_2_joint' type='revolute'>
        <child>arm_2_link</child>
        <parent>arm_1_link</parent>
        <axis>
          <xyz>-1 0 0</xyz>
          <limit>
            <lower>-1.9635</lower>
            <upper>0.785398</upper>
            <effort>39</effort>
            <velocity>3.66</velocity>
          </limit>
          <dynamics>
            <damping>1</damping>
            <friction>1</friction>
            <spring_reference>0</spring_reference>
            <spring_stiffness>0</spring_stiffness>
          </dynamics>
          <use_parent_model_frame>1</use_parent_model_frame>
        </axis>
        <physics>
          <ode>
            <implicit_spring_damper>1</implicit_spring_damper>
            <cfm_damping>1</cfm_damping>
            <limit>
              <cfm>0</cfm>
              <erp>0.2</erp>
            </limit>
          </ode>
        </physics>
      </joint>
      <link name='arm_3_link'>
        <pose frame=''>0.095 -0.197375 0.6568 1.5708 -0 -3.14159</pose>
        <inertial>
          <pose frame=''>0.00557 -0.01042 -0.10388 0 -0 0</pose>
          <mass>1.79881</mass>
          <inertia>
            <ixx>0.0268261</ixx>
            <ixy>-0.000196922</ixy>
            <ixz>-0.00150453</ixz>
            <iyy>0.0263805</iyy>
            <iyz>0.00263989</iyz>
            <izz>0.00238502</izz>
          </inertia>
        </inertial>
        <collision name='arm_3_link_collision'>
          <pose frame=''>0 0 -0.055 0 -0 0</pose>
          <geometry>
            <mesh>
              <scale>1 1 1</scale>
              <uri>/home/jasper/omni_marco_gazebo/src/robot_models/marco/marco_description/meshes/arm/arm_3_collision.stl</uri>
            </mesh>
          </geometry>
          <surface>
            <contact>
              <ode/>
            </contact>
            <friction>
              <ode>
                <mu>0.9</mu>
                <mu2>0.9</mu2>
              </ode>
              <torsional>
                <ode/>
              </torsional>
            </friction>
            <bounce/>
          </surface>
          <max_contacts>10</max_contacts>
        </collision>
        <collision name='arm_3_link_collision_1'>
          <pose frame=''>0 0 0 0 -0 0</pose>
          <geometry>
            <cylinder>
              <length>0.07</length>
              <radius>0.05</radius>
            </cylinder>
          </geometry>
          <surface>
            <contact>
              <ode/>
            </contact>
            <friction>
              <ode>
                <mu>0.9</mu>
                <mu2>0.9</mu2>
              </ode>
              <torsional>
                <ode/>
              </torsional>
            </friction>
            <bounce/>
          </surface>
          <max_contacts>10</max_contacts>
        </collision>
        <visual name='arm_3_link_visual'>
          <pose frame=''>0 0 -0.055 0 -0 0</pose>
          <geometry>
            <mesh>
              <scale>1 1 1</scale>
              <uri>/home/jasper/omni_marco_gazebo/src/robot_models/marco/marco_description/meshes/arm/arm_3.dae</uri>
            </mesh>
          </geometry>
          <material>
            <script>
              <name>Gazebo/DarkGrey</name>
              <uri>file://media/materials/scripts/gazebo.material</uri>
            </script>
          </material>
        </visual>
        <visual name='arm_3_link_visual_1'>
          <pose frame=''>0 0 0 0 -0 0</pose>
          <geometry>
            <cylinder>
              <length>0.07</length>
              <radius>0.05</radius>
            </cylinder>
          </geometry>
          <material>
            <script>
              <name>Gazebo/DarkGrey</name>
              <uri>file://media/materials/scripts/gazebo.material</uri>
            </script>
          </material>
        </visual>
        <gravity>1</gravity>
        <velocity_decay/>
        <self_collide>0</self_collide>
        <kinematic>0</kinematic>
      </link>
      <joint name='arm_3_joint' type='revolute'>
        <child>arm_3_link</child>
        <parent>arm_2_link</parent>
        <axis>
          <xyz>0 1 0</xyz>
          <limit>
            <lower>-3.49066</lower>
            <upper>1.5708</upper>
            <effort>17.86</effort>
            <velocity>4.58</velocity>
          </limit>
          <dynamics>
            <damping>1</damping>
            <friction>1</friction>
            <spring_reference>0</spring_reference>
            <spring_stiffness>0</spring_stiffness>
          </dynamics>
          <use_parent_model_frame>1</use_parent_model_frame>
        </axis>
        <physics>
          <ode>
            <implicit_spring_damper>1</implicit_spring_damper>
            <cfm_damping>1</cfm_damping>
            <limit>
              <cfm>0</cfm>
              <erp>0.2</erp>
            </limit>
          </ode>
        </physics>
      </joint>
      <link name='arm_4_link'>
        <pose frame=''>0.095 -0.339375 0.6368 1.5708 -0 1.5708</pose>
        <inertial>
          <pose frame=''>-0.06578 0.0126 0.01194 0 -0 0</pose>
          <mass>1.35076</mass>
          <inertia>
            <ixx>0.0022051</ixx>
            <ixy>-0.0016549</ixy>
            <ixz>-0.000227733</ixz>
            <iyy>0.0117763</iyy>
            <iyz>3.47243e-05</iyz>
            <izz>0.0120919</izz>
          </inertia>
        </inertial>
        <collision name='arm_4_link_collision'>
          <pose frame=''>0 0 0 0 -0 0</pose>
          <geometry>
            <mesh>
              <scale>1 1 1</scale>
              <uri>/home/jasper/omni_marco_gazebo/src/robot_models/marco/marco_description/meshes/arm/arm_4_collision.stl</uri>
            </mesh>
          </geometry>
          <surface>
            <contact>
              <ode/>
            </contact>
            <friction>
              <ode>
                <mu>0.9</mu>
                <mu2>0.9</mu2>
              </ode>
              <torsional>
                <ode/>
              </torsional>
            </friction>
            <bounce/>
          </surface>
          <max_contacts>10</max_contacts>
        </collision>
        <collision name='arm_4_link_collision_1'>
          <pose frame=''>-0.15 0.02 0 3.14159 1.57079 3.14159</pose>
          <geometry>
            <cylinder>
              <length>0.07</length>
              <radius>0.05</radius>
            </cylinder>
          </geometry>
          <surface>
            <contact>
              <ode/>
            </contact>
            <friction>
              <ode>
                <mu>0.9</mu>
                <mu2>0.9</mu2>
              </ode>
              <torsional>
                <ode/>
              </torsional>
            </friction>
            <bounce/>
          </surface>
          <max_contacts>10</max_contacts>
        </collision>
        <visual name='arm_4_link_visual'>
          <pose frame=''>0 0 0 0 -0 0</pose>
          <geometry>
            <mesh>
              <scale>1 1 1</scale>
              <uri>/home/jasper/omni_marco_gazebo/src/robot_models/marco/marco_description/meshes/arm/arm_4.dae</uri>
            </mesh>
          </geometry>
          <material>
            <script>
              <name>Gazebo/DarkGrey</name>
              <uri>file://media/materials/scripts/gazebo.material</uri>
            </script>
          </material>
        </visual>
        <visual name='arm_4_link_visual_1'>
          <pose frame=''>-0.15 0.02 0 3.14159 1.57079 3.14159</pose>
          <geometry>
            <cylinder>
              <length>0.07</length>
              <radius>0.05</radius>
            </cylinder>
          </geometry>
          <material>
            <script>
              <name>Gazebo/DarkGrey</name>
              <uri>file://media/materials/scripts/gazebo.material</uri>
            </script>
          </material>
        </visual>
        <gravity>1</gravity>
        <velocity_decay/>
        <self_collide>0</self_collide>
        <kinematic>0</kinematic>
      </link>
      <joint name='arm_4_joint' type='revolute'>
        <child>arm_4_link</child>
        <parent>arm_3_link</parent>
        <axis>
          <xyz>1 0 0</xyz>
          <limit>
            <lower>-0.785398</lower>
            <upper>2.35619</upper>
            <effort>17.86</effort>
            <velocity>4.58</velocity>
          </limit>
          <dynamics>
            <damping>1</damping>
            <friction>1</friction>
            <spring_reference>0</spring_reference>
            <spring_stiffness>0</spring_stiffness>
          </dynamics>
          <use_parent_model_frame>1</use_parent_model_frame>
        </axis>
        <physics>
          <ode>
            <implicit_spring_damper>1</implicit_spring_damper>
            <cfm_damping>1</cfm_damping>
            <limit>
              <cfm>0</cfm>
              <erp>0.2</erp>
            </limit>
          </ode>
        </physics>
      </joint>
      <link name='arm_5_link'>
        <pose frame=''>0.095 -0.492375 0.6568 1.5708 -0 0</pose>
        <inertial>
          <pose frame=''>-0.00084 1e-05 0.07797 0 -0 0</pose>
          <mass>1.32698</mass>
          <inertia>
            <ixx>0.0104957</ixx>
            <ixy>-3.16264e-06</ixy>
            <ixz>-0.000125481</ixz>
            <iyy>0.0102884</iyy>
            <iyz>2.7891e-06</iyz>
            <izz>0.000944199</izz>
          </inertia>
        </inertial>
        <collision name='arm_5_link_collision'>
          <pose frame=''>0 0 0 0 -0 0</pose>
          <geometry>
            <mesh>
              <scale>1 1 1</scale>
              <uri>/home/jasper/omni_marco_gazebo/src/robot_models/marco/marco_description/meshes/arm/arm_5_collision.stl</uri>
            </mesh>
          </geometry>
          <surface>
            <contact>
              <ode/>
            </contact>
            <friction>
              <ode>
                <mu>0.9</mu>
                <mu2>0.9</mu2>
              </ode>
              <torsional>
                <ode/>
              </torsional>
            </friction>
            <bounce/>
          </surface>
          <max_contacts>10</max_contacts>
        </collision>
        <visual name='arm_5_link_visual'>
          <pose frame=''>0 0 0 0 -0 0</pose>
          <geometry>
            <mesh>
              <scale>1 1 1</scale>
              <uri>/home/jasper/omni_marco_gazebo/src/robot_models/marco/marco_description/meshes/arm/arm_5.dae</uri>
            </mesh>
          </geometry>
          <material>
            <script>
              <uri>__default__</uri>
              <name>__default__</name>
            </script>
          </material>
        </visual>
        <gravity>1</gravity>
        <velocity_decay/>
        <self_collide>0</self_collide>
        <kinematic>0</kinematic>
      </link>
      <joint name='arm_5_joint' type='revolute'>
        <child>arm_5_link</child>
        <parent>arm_4_link</parent>
        <axis>
          <xyz>0 -1 0</xyz>
          <limit>
            <lower>-2.0944</lower>
            <upper>2.0944</upper>
            <effort>3</effort>
            <velocity>1.95</velocity>
          </limit>
          <dynamics>
            <damping>1</damping>
            <friction>1</friction>
            <spring_reference>0</spring_reference>
            <spring_stiffness>0</spring_stiffness>
          </dynamics>
          <use_parent_model_frame>1</use_parent_model_frame>
        </axis>
        <physics>
          <ode>
            <implicit_spring_damper>1</implicit_spring_damper>
            <cfm_damping>1</cfm_damping>
            <limit>
              <cfm>0</cfm>
              <erp>0.2</erp>
            </limit>
          </ode>
        </physics>
      </joint>
      <link name='arm_6_link'>
        <pose frame=''>0.095 -0.642375 0.6568 0 -0 0</pose>
        <inertial>
          <pose frame=''>-1.4e-05 -0.00368 1e-05 0 -0 0</pose>
          <mass>0.35781</mass>
          <inertia>
            <ixx>0.000164895</ixx>
            <ixy>2.779e-07</ixy>
            <ixz>9.308e-08</ixz>
            <iyy>0.00013155</iyy>
            <iyz>7.106e-08</iyz>
            <izz>0.000119988</izz>
          </inertia>
        </inertial>
        <collision name='arm_6_link_collision'>
          <pose frame=''>0 0 0 0 -0 0</pose>
          <geometry>
            <cylinder>
              <length>0.0385</length>
              <radius>0.04</radius>
            </cylinder>
          </geometry>
          <surface>
            <contact>
              <ode/>
            </contact>
            <friction>
              <ode>
                <mu>0.9</mu>
                <mu2>0.9</mu2>
              </ode>
              <torsional>
                <ode/>
              </torsional>
            </friction>
            <bounce/>
          </surface>
          <max_contacts>10</max_contacts>
        </collision>
        <visual name='arm_6_link_visual'>
          <pose frame=''>0 0 0 0 -0 0</pose>
          <geometry>
            <mesh>
              <scale>1 1 1</scale>
              <uri>/home/jasper/omni_marco_gazebo/src/robot_models/marco/marco_description/meshes/arm/arm_6.dae</uri>
            </mesh>
          </geometry>
          <material>
            <script>
              <uri>__default__</uri>
              <name>__default__</name>
            </script>
          </material>
        </visual>
        <gravity>1</gravity>
        <velocity_decay/>
        <self_collide>0</self_collide>
        <kinematic>0</kinematic>
      </link>
      <joint name='arm_6_joint' type='revolute'>
        <child>arm_6_link</child>
        <parent>arm_5_link</parent>
        <axis>
          <xyz>0 0 1</xyz>
          <limit>
            <lower>-1.5708</lower>
            <upper>1.5708</upper>
            <effort>6.6</effort>
            <velocity>1.76</velocity>
          </limit>
          <dynamics>
            <damping>1</damping>
            <friction>1</friction>
            <spring_reference>0</spring_reference>
            <spring_stiffness>0</spring_stiffness>
          </dynamics>
          <use_parent_model_frame>1</use_parent_model_frame>
        </axis>
        <physics>
          <ode>
            <implicit_spring_damper>1</implicit_spring_damper>
            <cfm_damping>1</cfm_damping>
            <limit>
              <cfm>0</cfm>
              <erp>0.2</erp>
            </limit>
          </ode>
        </physics>
      </joint>
      <link name='arm_7_link'>
        <pose frame=''>0.095 -0.642375 0.6568 1.5708 -0 0</pose>
        <inertial>
          <pose frame=''>0.000282 -0.003318 0.034521 0 -0 0</pose>
          <mass>1.20123</mass>
          <inertia>
            <ixx>0.00407639</ixx>
            <ixy>9.17856e-06</ixy>
            <ixz>-2.85746e-05</ixz>
            <iyy>0.00403913</iyy>
            <iyz>0.000332215</iyz>
            <izz>0.000266523</izz>
          </inertia>
        </inertial>
        <collision name='arm_7_link_collision'>
          <pose frame=''>0 0 0.0345 0 -0 0</pose>
          <geometry>
            <cylinder>
              <length>0.023</length>
              <radius>0.02</radius>
            </cylinder>
          </geometry>
          <surface>
            <contact>
              <ode>
                <kp>1e+06</kp>
                <kd>100</kd>
                <max_vel>1</max_vel>
                <min_depth>0</min_depth>
              </ode>
            </contact>
            <friction>
              <ode>
                <fdir1>1 0 0</fdir1>
                <mu>0.9</mu>
                <mu2>0.9</mu2>
              </ode>
              <torsional>
                <ode/>
              </torsional>
            </friction>
            <bounce/>
          </surface>
          <max_contacts>10</max_contacts>
        </collision>
        <collision name='arm_7_link_fixed_joint_lump__arm_tool_link_collision_1'>
          <pose frame=''>-0 0 0.047 0 -0 -1.5708</pose>
          <geometry>
            <cylinder>
              <length>0.005</length>
              <radius>0.005</radius>
            </cylinder>
          </geometry>
          <max_contacts>10</max_contacts>
          <surface>
            <contact>
              <ode/>
            </contact>
            <bounce/>
            <friction>
              <torsional>
                <ode/>
              </torsional>
              <ode/>
            </friction>
          </surface>
        </collision>
        <collision name='arm_7_link_fixed_joint_lump__wrist_ft_link_collision_2'>
          <pose frame=''>-0 0 0.05385 -0 -0 -0</pose>
          <geometry>
            <cylinder>
              <length>0.0157</length>
              <radius>0.0225</radius>
            </cylinder>
          </geometry>
          <max_contacts>10</max_contacts>
          <surface>
            <contact>
              <ode/>
            </contact>
            <bounce/>
            <friction>
              <torsional>
                <ode/>
              </torsional>
              <ode/>
            </friction>
          </surface>
        </collision>
        <collision name='arm_7_link_fixed_joint_lump__wrist_ft_tool_link_collision_3'>
          <pose frame=''>-0 0 0.066575 0 -0 -1.5708</pose>
          <geometry>
            <cylinder>
              <length>0.00975</length>
              <radius>0.025</radius>
            </cylinder>
          </geometry>
          <max_contacts>10</max_contacts>
          <surface>
            <contact>
              <ode/>
            </contact>
            <bounce/>
            <friction>
              <torsional>
                <ode/>
              </torsional>
              <ode/>
            </friction>
          </surface>
        </collision>
        <collision name='arm_7_link_fixed_joint_lump__gripper_wrist_link_collision_4'>
          <pose frame=''>-0 0 0.095575 -1.5708 -0 -3.14159</pose>
          <geometry>
            <mesh>
              <scale>1 1 1</scale>
              <uri>/home/jasper/omni_marco_gazebo/src/robot_models/marco/hit_gripper/hit_gripper_description/meshes/wrist_mount.stl</uri>
            </mesh>
          </geometry>
          <surface>
            <contact>
              <ode/>
            </contact>
            <friction>
              <ode/>
              <torsional>
                <ode/>
              </torsional>
            </friction>
            <bounce/>
          </surface>
          <max_contacts>10</max_contacts>
        </collision>
        <collision name='arm_7_link_fixed_joint_lump__gripper_body_link_collision_5'>
          <pose frame=''>-0 0 0.095575 1.5708 -0 -3.14159</pose>
          <geometry>
            <mesh>
              <scale>1 1 1</scale>
              <uri>/home/jasper/omni_marco_gazebo/src/robot_models/marco/hit_gripper/hit_gripper_description/meshes/body.stl</uri>
            </mesh>
          </geometry>
          <surface>
            <contact>
              <ode/>
            </contact>
            <friction>
              <ode/>
              <torsional>
                <ode/>
              </torsional>
            </friction>
            <bounce/>
          </surface>
          <max_contacts>10</max_contacts>
        </collision>
        <collision name='arm_7_link_fixed_joint_lump__gripper_camera_mount_link_collision_6'>
          <pose frame=''>-0.03 -0.014 0.115575 0 -0.261799 3.14159</pose>
          <geometry>
            <mesh>
              <scale>1 1 1</scale>
              <uri>/home/jasper/omni_marco_gazebo/src/robot_models/marco/hit_gripper/hit_gripper_description/meshes/camera_mount.stl</uri>
            </mesh>
          </geometry>
          <surface>
            <contact>
              <ode/>
            </contact>
            <friction>
              <ode/>
              <torsional>
                <ode/>
              </torsional>
            </friction>
            <bounce/>
          </surface>
          <max_contacts>10</max_contacts>
        </collision>
        <collision name='arm_7_link_fixed_joint_lump__end_effector_cam_link_collision_7'>
          <pose frame=''>-0.03 -0.035 0.115575 0 -0.261799 3.14159</pose>
          <geometry>
            <cylinder>
              <length>0.04</length>
              <radius>0.014</radius>
            </cylinder>
          </geometry>
          <max_contacts>10</max_contacts>
          <surface>
            <contact>
              <ode/>
            </contact>
            <bounce/>
            <friction>
              <torsional>
                <ode/>
              </torsional>
              <ode/>
            </friction>
          </surface>
        </collision>
        <visual name='arm_7_link_visual'>
          <pose frame=''>0 0 0.046 0 -0 0</pose>
          <geometry>
            <cylinder>
              <length>0.005</length>
              <radius>0.02</radius>
            </cylinder>
          </geometry>
          <material>
            <script>
              <uri>__default__</uri>
              <name>__default__</name>
            </script>
          </material>
        </visual>
        <visual name='arm_7_link_fixed_joint_lump__arm_tool_link_visual_1'>
          <pose frame=''>-0 0 0.047 0 -0 -1.5708</pose>
          <geometry>
            <cylinder>
              <length>0.005</length>
              <radius>0.005</radius>
            </cylinder>
          </geometry>
        </visual>
        <visual name='arm_7_link_fixed_joint_lump__wrist_ft_link_visual_2'>
          <pose frame=''>-0 0 0.05385 -0 -0 -0</pose>
          <geometry>
            <cylinder>
              <length>0.0157</length>
              <radius>0.0225</radius>
            </cylinder>
          </geometry>
        </visual>
        <visual name='arm_7_link_fixed_joint_lump__wrist_ft_tool_link_visual_3'>
          <pose frame=''>-0 0 0.066575 0 -0 -1.5708</pose>
          <geometry>
            <cylinder>
              <length>0.00975</length>
              <radius>0.025</radius>
            </cylinder>
          </geometry>
        </visual>
        <visual name='arm_7_link_fixed_joint_lump__gripper_wrist_link_visual_4'>
          <pose frame=''>-0 0 0.095575 -1.5708 -0 -3.14159</pose>
          <geometry>
            <mesh>
              <scale>1 1 1</scale>
              <uri>/home/jasper/omni_marco_gazebo/src/robot_models/marco/hit_gripper/hit_gripper_description/meshes/wrist_mount.stl</uri>
            </mesh>
          </geometry>
          <material>
            <script>
              <name>Gazebo/White</name>
              <uri>file://media/materials/scripts/gazebo.material</uri>
            </script>
          </material>
        </visual>
        <visual name='arm_7_link_fixed_joint_lump__gripper_body_link_visual_5'>
          <pose frame=''>-0 0 0.095575 1.5708 -0 -3.14159</pose>
          <geometry>
            <mesh>
              <scale>1 1 1</scale>
              <uri>/home/jasper/omni_marco_gazebo/src/robot_models/marco/hit_gripper/hit_gripper_description/meshes/body.stl</uri>
            </mesh>
          </geometry>
          <material>
            <script>
              <name>Gazebo/White</name>
              <uri>file://media/materials/scripts/gazebo.material</uri>
            </script>
          </material>
        </visual>
        <visual name='arm_7_link_fixed_joint_lump__gripper_camera_mount_link_visual_6'>
          <pose frame=''>-0.03 -0.014 0.115575 0 -0.261799 3.14159</pose>
          <geometry>
            <mesh>
              <scale>1 1 1</scale>
              <uri>/home/jasper/omni_marco_gazebo/src/robot_models/marco/hit_gripper/hit_gripper_description/meshes/camera_mount.stl</uri>
            </mesh>
          </geometry>
          <material>
            <script>
              <name>Gazebo/White</name>
              <uri>file://media/materials/scripts/gazebo.material</uri>
            </script>
          </material>
        </visual>
        <visual name='arm_7_link_fixed_joint_lump__end_effector_cam_link_visual_7'>
          <pose frame=''>-0.03 -0.035 0.115575 0 -0.261799 3.14159</pose>
          <geometry>
            <cylinder>
              <length>0.04</length>
              <radius>0.014</radius>
            </cylinder>
          </geometry>
        </visual>
        <visual name='arm_7_link_fixed_joint_lump__gripper_motor_link_visual_8'>
          <pose frame=''>0.00515 -0.0315 0.130875 1.5708 -0 -3.14159</pose>
          <geometry>
            <mesh>
              <scale>1 1 1</scale>
              <uri>/home/jasper/omni_marco_gazebo/src/robot_models/marco/hit_gripper/hit_gripper_description/meshes/motor.stl</uri>
            </mesh>
          </geometry>
          <material>
            <script>
              <name>Gazebo/FlatBlack</name>
              <uri>file://media/materials/scripts/gazebo.material</uri>
            </script>
          </material>
        </visual>
        <velocity_decay/>
        <velocity_decay/>
        <velocity_decay/>
        <velocity_decay/>
        <velocity_decay/>
        <velocity_decay/>
        <sensor name='end_effector_cam' type='camera'>
          <update_rate>30</update_rate>
          <camera name='end_effector_cam'>
            <horizontal_fov>1.39626</horizontal_fov>
            <image>
              <width>1280</width>
              <height>720</height>
              <format>R8G8B8</format>
            </image>
            <clip>
              <near>0.02</near>
              <far>300</far>
            </clip>
            <noise>
              <type>gaussian</type>
              <mean>0</mean>
              <stddev>0.007</stddev>
            </noise>
          </camera>
          <plugin name='camera_controller' filename='libgazebo_ros_camera.so'>
            <alwaysOn>true</alwaysOn>
            <updateRate>0.0</updateRate>
            <cameraName>end_effector_cam</cameraName>
            <imageTopicName>image_raw</imageTopicName>
            <cameraInfoTopicName>camera_info</cameraInfoTopicName>
            <frameName>end_effector_cam_optical_frame</frameName>
            <hackBaseline>0.0</hackBaseline>
            <distortionK1>0.0</distortionK1>
            <distortionK2>0.0</distortionK2>
            <distortionK3>0.0</distortionK3>
            <distortionT1>0.0</distortionT1>
            <distortionT2>0.0</distortionT2>
            <CxPrime>0</CxPrime>
            <Cx>0.0</Cx>
            <Cy>0.0</Cy>
            <focalLength>0.0</focalLength>
            <robotNamespace>/</robotNamespace>
          </plugin>
          <pose frame=''>-0.02353 -0.035 0.139723 1.5708 -1.309 -0</pose>
        </sensor>
        <gravity>1</gravity>
        <velocity_decay/>
        <self_collide>0</self_collide>
        <kinematic>0</kinematic>
      </link>
      <joint name='arm_7_joint' type='revolute'>
        <child>arm_7_link</child>
        <parent>arm_6_link</parent>
        <axis>
          <xyz>0 -1 0</xyz>
          <limit>
            <lower>-2.0944</lower>
            <upper>2.0944</upper>
            <effort>6.6</effort>
            <velocity>1.76</velocity>
          </limit>
          <dynamics>
            <damping>1</damping>
            <friction>1</friction>
            <spring_reference>0</spring_reference>
            <spring_stiffness>0</spring_stiffness>
          </dynamics>
          <use_parent_model_frame>1</use_parent_model_frame>
        </axis>
        <physics>
          <provide_feedback>1</provide_feedback>
          <ode>
            <provide_feedback>1</provide_feedback>
            <implicit_spring_damper>1</implicit_spring_damper>
            <cfm_damping>1</cfm_damping>
            <limit>
              <cfm>0</cfm>
              <erp>0.2</erp>
            </limit>
          </ode>
        </physics>
      </joint>
      <link name='gripper_finger_inner_left_link'>
        <pose frame=''>0.076 -0.7972 0.6568 -3.14159 -0 -3.14159</pose>
        <inertial>
          <pose frame=''>0 -0.0185 0 0 -0 0</pose>
          <mass>0.02</mass>
          <inertia>
            <ixx>7.8e-06</ixx>
            <ixy>5.7e-07</ixy>
            <ixz>-0</ixz>
            <iyy>1.01e-06</iyy>
            <iyz>-3e-08</iyz>
            <izz>7.81e-06</izz>
          </inertia>
        </inertial>
        <visual name='gripper_finger_inner_left_link_visual'>
          <pose frame=''>0 0 0 0 -0 0</pose>
          <geometry>
            <mesh>
              <scale>1 1 1</scale>
              <uri>/home/jasper/omni_marco_gazebo/src/robot_models/marco/hit_gripper/hit_gripper_description/meshes/finger_inner_left.stl</uri>
            </mesh>
          </geometry>
          <material>
            <script>
              <name>Gazebo/White</name>
              <uri>file://media/materials/scripts/gazebo.material</uri>
            </script>
          </material>
        </visual>
        <gravity>1</gravity>
        <velocity_decay/>
        <self_collide>0</self_collide>
        <kinematic>0</kinematic>
      </link>
      <joint name='gripper_finger_inner_left_joint' type='revolute'>
        <child>gripper_finger_inner_left_link</child>
        <parent>arm_7_link</parent>
        <axis>
          <xyz>0 0 -1</xyz>
          <limit>
            <lower>-0.226893</lower>
            <upper>1.0472</upper>
            <effort>1</effort>
            <velocity>1</velocity>
          </limit>
          <dynamics>
            <damping>1</damping>
            <friction>1</friction>
            <spring_reference>0</spring_reference>
            <spring_stiffness>0</spring_stiffness>
          </dynamics>
          <use_parent_model_frame>1</use_parent_model_frame>
        </axis>
        <physics>
          <provide_feedback>1</provide_feedback>
          <ode>
            <provide_feedback>1</provide_feedback>
            <implicit_spring_damper>1</implicit_spring_damper>
            <cfm_damping>1</cfm_damping>
            <limit>
              <cfm>0</cfm>
              <erp>0.2</erp>
            </limit>
          </ode>
        </physics>
      </joint>
      <link name='gripper_finger_tip_left_link'>
        <pose frame=''>0.076 -0.8542 0.6568 0 -0 -3.14159</pose>
        <inertial>
          <pose frame=''>0.0035 0.01 0 0 -0 0</pose>
          <mass>0.0137</mass>
          <inertia>
            <ixx>1.77e-06</ixx>
            <ixy>4.4e-07</ixy>
            <ixz>-0</ixz>
            <iyy>6.2e-07</iyy>
            <iyz>0</iyz>
            <izz>1.9e-06</izz>
          </inertia>
        </inertial>
        <collision name='gripper_finger_tip_left_link_collision'>
          <pose frame=''>0 0 0 0 -0 0</pose>
          <geometry>
            <mesh>
              <scale>1 1 1</scale>
              <uri>/home/jasper/omni_marco_gazebo/src/robot_models/marco/hit_gripper/hit_gripper_description/meshes/finger_tip.stl</uri>
            </mesh>
          </geometry>
          <surface>
            <contact>
              <ode/>
            </contact>
            <friction>
              <ode/>
              <torsional>
                <ode/>
              </torsional>
            </friction>
            <bounce/>
          </surface>
          <max_contacts>10</max_contacts>
        </collision>
        <visual name='gripper_finger_tip_left_link_visual'>
          <pose frame=''>0 0 0 0 -0 0</pose>
          <geometry>
            <mesh>
              <scale>1 1 1</scale>
              <uri>/home/jasper/omni_marco_gazebo/src/robot_models/marco/hit_gripper/hit_gripper_description/meshes/finger_tip.stl</uri>
            </mesh>
          </geometry>
          <material>
            <script>
              <name>Gazebo/White</name>
              <uri>file://media/materials/scripts/gazebo.material</uri>
            </script>
          </material>
        </visual>
        <gravity>1</gravity>
        <velocity_decay/>
        <self_collide>0</self_collide>
        <kinematic>0</kinematic>
      </link>
      <joint name='gripper_finger_tip_left_joint' type='revolute'>
        <child>gripper_finger_tip_left_link</child>
        <parent>gripper_finger_inner_left_link</parent>
        <axis>
          <xyz>0 0 1</xyz>
          <limit>
            <lower>-0.226893</lower>
            <upper>1.0472</upper>
            <effort>1</effort>
            <velocity>1</velocity>
          </limit>
          <dynamics>
            <damping>1</damping>
            <friction>1</friction>
            <spring_reference>0</spring_reference>
            <spring_stiffness>0</spring_stiffness>
          </dynamics>
          <use_parent_model_frame>1</use_parent_model_frame>
        </axis>
        <physics>
          <provide_feedback>1</provide_feedback>
          <ode>
            <provide_feedback>1</provide_feedback>
            <implicit_spring_damper>1</implicit_spring_damper>
            <cfm_damping>1</cfm_damping>
            <limit>
              <cfm>0</cfm>
              <erp>0.2</erp>
            </limit>
          </ode>
        </physics>
      </joint>
      <link name='gripper_finger_inner_right_link'>
        <pose frame=''>0.114 -0.7972 0.6569 3.14159 -0 0</pose>
        <inertial>
          <pose frame=''>-0.00157 0.017 0 0 -0 0</pose>
          <mass>0.02</mass>
          <inertia>
            <ixx>7.55e-06</ixx>
            <ixy>-4.1e-07</ixy>
            <ixz>-0</ixz>
            <iyy>9.1e-07</iyy>
            <iyz>3e-08</iyz>
            <izz>7.62e-06</izz>
          </inertia>
        </inertial>
        <visual name='gripper_finger_inner_right_link_visual'>
          <pose frame=''>0 0 0 0 -0 0</pose>
          <geometry>
            <mesh>
              <scale>1 1 1</scale>
              <uri>/home/jasper/omni_marco_gazebo/src/robot_models/marco/hit_gripper/hit_gripper_description/meshes/finger_inner_right.stl</uri>
            </mesh>
          </geometry>
          <material>
            <script>
              <name>Gazebo/White</name>
              <uri>file://media/materials/scripts/gazebo.material</uri>
            </script>
          </material>
        </visual>
        <gravity>1</gravity>
        <velocity_decay/>
        <self_collide>0</self_collide>
        <kinematic>0</kinematic>
      </link>
      <joint name='gripper_finger_inner_right_joint' type='revolute'>
        <child>gripper_finger_inner_right_link</child>
        <parent>arm_7_link</parent>
        <axis>
          <xyz>0 0 -1</xyz>
          <limit>
            <lower>-1.0472</lower>
            <upper>0.226893</upper>
            <effort>1</effort>
            <velocity>1</velocity>
          </limit>
          <dynamics>
            <damping>1</damping>
            <friction>1</friction>
            <spring_reference>0</spring_reference>
            <spring_stiffness>0</spring_stiffness>
          </dynamics>
          <use_parent_model_frame>1</use_parent_model_frame>
        </axis>
        <physics>
          <provide_feedback>1</provide_feedback>
          <ode>
            <provide_feedback>1</provide_feedback>
            <implicit_spring_damper>1</implicit_spring_damper>
            <cfm_damping>1</cfm_damping>
            <limit>
              <cfm>0</cfm>
              <erp>0.2</erp>
            </limit>
          </ode>
        </physics>
      </joint>
      <link name='gripper_finger_tip_right_link'>
        <pose frame=''>0.114 -0.8542 0.6569 3.14159 -0 0</pose>
        <inertial>
          <pose frame=''>0.0035 0.01 0 0 -0 0</pose>
          <mass>0.0137</mass>
          <inertia>
            <ixx>1.77e-06</ixx>
            <ixy>4.4e-07</ixy>
            <ixz>-0</ixz>
            <iyy>6.2e-07</iyy>
            <iyz>0</iyz>
            <izz>1.9e-06</izz>
          </inertia>
        </inertial>
        <collision name='gripper_finger_tip_right_link_collision'>
          <pose frame=''>0 0 0 0 -0 0</pose>
          <geometry>
            <mesh>
              <scale>1 1 1</scale>
              <uri>/home/jasper/omni_marco_gazebo/src/robot_models/marco/hit_gripper/hit_gripper_description/meshes/finger_tip.stl</uri>
            </mesh>
          </geometry>
          <surface>
            <contact>
              <ode/>
            </contact>
            <friction>
              <ode/>
              <torsional>
                <ode/>
              </torsional>
            </friction>
            <bounce/>
          </surface>
          <max_contacts>10</max_contacts>
        </collision>
        <visual name='gripper_finger_tip_right_link_visual'>
          <pose frame=''>0 0 0 0 -0 0</pose>
          <geometry>
            <mesh>
              <scale>1 1 1</scale>
              <uri>/home/jasper/omni_marco_gazebo/src/robot_models/marco/hit_gripper/hit_gripper_description/meshes/finger_tip.stl</uri>
            </mesh>
          </geometry>
          <material>
            <script>
              <name>Gazebo/White</name>
              <uri>file://media/materials/scripts/gazebo.material</uri>
            </script>
          </material>
        </visual>
        <gravity>1</gravity>
        <velocity_decay/>
        <self_collide>0</self_collide>
        <kinematic>0</kinematic>
      </link>
      <joint name='gripper_finger_tip_right_joint' type='revolute'>
        <child>gripper_finger_tip_right_link</child>
        <parent>gripper_finger_inner_right_link</parent>
        <axis>
          <xyz>0 0 -1</xyz>
          <limit>
            <lower>-0.226893</lower>
            <upper>1.0472</upper>
            <effort>1</effort>
            <velocity>1</velocity>
          </limit>
          <dynamics>
            <damping>1</damping>
            <friction>1</friction>
            <spring_reference>0</spring_reference>
            <spring_stiffness>0</spring_stiffness>
          </dynamics>
          <use_parent_model_frame>1</use_parent_model_frame>
        </axis>
        <physics>
          <provide_feedback>1</provide_feedback>
          <ode>
            <provide_feedback>1</provide_feedback>
            <implicit_spring_damper>1</implicit_spring_damper>
            <cfm_damping>1</cfm_damping>
            <limit>
              <cfm>0</cfm>
              <erp>0.2</erp>
            </limit>
          </ode>
        </physics>
      </joint>
      <link name='gripper_finger_outer_left_link'>
        <pose frame=''>0.061865 -0.7897 0.6567 3.14159 -0 0.05585</pose>
        <inertial>
          <pose frame=''>-0.005 0.031 0 0 -0 0</pose>
          <mass>0.0125</mass>
          <inertia>
            <ixx>3.35e-06</ixx>
            <ixy>7e-08</ixy>
            <ixz>-0</ixz>
            <iyy>4.9e-07</iyy>
            <iyz>0</iyz>
            <izz>3.03e-06</izz>
          </inertia>
        </inertial>
        <visual name='gripper_finger_outer_left_link_visual'>
          <pose frame=''>0 0 0 0 -0 0</pose>
          <geometry>
            <mesh>
              <scale>1 1 1</scale>
              <uri>/home/jasper/omni_marco_gazebo/src/robot_models/marco/hit_gripper/hit_gripper_description/meshes/finger_outer.stl</uri>
            </mesh>
          </geometry>
          <material>
            <script>
              <name>Gazebo/White</name>
              <uri>file://media/materials/scripts/gazebo.material</uri>
            </script>
          </material>
        </visual>
        <gravity>1</gravity>
        <velocity_decay/>
        <self_collide>0</self_collide>
        <kinematic>0</kinematic>
      </link>
      <joint name='gripper_finger_outer_left_joint' type='revolute'>
        <child>gripper_finger_outer_left_link</child>
        <parent>arm_7_link</parent>
        <axis>
          <xyz>0 0 -1</xyz>
          <limit>
            <lower>-0.226893</lower>
            <upper>1.0472</upper>
            <effort>1</effort>
            <velocity>1</velocity>
          </limit>
          <dynamics>
            <damping>1</damping>
            <friction>1</friction>
            <spring_reference>0</spring_reference>
            <spring_stiffness>0</spring_stiffness>
          </dynamics>
          <use_parent_model_frame>1</use_parent_model_frame>
        </axis>
        <physics>
          <provide_feedback>1</provide_feedback>
          <ode>
            <provide_feedback>1</provide_feedback>
            <implicit_spring_damper>1</implicit_spring_damper>
            <cfm_damping>1</cfm_damping>
            <limit>
              <cfm>0</cfm>
              <erp>0.2</erp>
            </limit>
          </ode>
        </physics>
      </joint>
      <link name='gripper_finger_outer_right_link'>
        <pose frame=''>0.128135 -0.7897 0.6568 0 -0 3.08574</pose>
        <inertial>
          <pose frame=''>-0.005 0.031 0 0 -0 0</pose>
          <mass>0.0125</mass>
          <inertia>
            <ixx>3.35e-06</ixx>
            <ixy>7e-08</ixy>
            <ixz>-0</ixz>
            <iyy>4.9e-07</iyy>
            <iyz>0</iyz>
            <izz>3.03e-06</izz>
          </inertia>
        </inertial>
        <visual name='gripper_finger_outer_right_link_visual'>
          <pose frame=''>0 0 0 0 -0 0</pose>
          <geometry>
            <mesh>
              <scale>1 1 1</scale>
              <uri>/home/jasper/omni_marco_gazebo/src/robot_models/marco/hit_gripper/hit_gripper_description/meshes/finger_outer.stl</uri>
            </mesh>
          </geometry>
          <material>
            <script>
              <name>Gazebo/White</name>
              <uri>file://media/materials/scripts/gazebo.material</uri>
            </script>
          </material>
        </visual>
        <gravity>1</gravity>
        <velocity_decay/>
        <self_collide>0</self_collide>
        <kinematic>0</kinematic>
      </link>
      <joint name='gripper_finger_outer_right_joint' type='revolute'>
        <child>gripper_finger_outer_right_link</child>
        <parent>arm_7_link</parent>
        <axis>
          <xyz>0 0 1</xyz>
          <limit>
            <lower>-0.226893</lower>
            <upper>1.0472</upper>
            <effort>1</effort>
            <velocity>1</velocity>
          </limit>
          <dynamics>
            <damping>1</damping>
            <friction>1</friction>
            <spring_reference>0</spring_reference>
            <spring_stiffness>0</spring_stiffness>
          </dynamics>
          <use_parent_model_frame>1</use_parent_model_frame>
        </axis>
        <physics>
          <provide_feedback>1</provide_feedback>
          <ode>
            <provide_feedback>1</provide_feedback>
            <implicit_spring_damper>1</implicit_spring_damper>
            <cfm_damping>1</cfm_damping>
            <limit>
              <cfm>0</cfm>
              <erp>0.2</erp>
            </limit>
          </ode>
        </physics>
      </joint>
      <link name='gripper_link'>
        <pose frame=''>0.1002 -0.77315 0.6568 0 -0 -3.14159</pose>
        <inertial>
          <pose frame=''>0 0 0.008 0 -0 0</pose>
          <mass>0.004</mass>
          <inertia>
            <ixx>1.5e-07</ixx>
            <ixy>0</ixy>
            <ixz>-0</ixz>
            <iyy>1.5e-07</iyy>
            <iyz>0</iyz>
            <izz>1.5e-07</izz>
          </inertia>
        </inertial>
        <visual name='gripper_link_visual'>
          <pose frame=''>0 0 0 0 -0 0</pose>
          <geometry>
            <mesh>
              <scale>1 1 1</scale>
              <uri>/home/jasper/omni_marco_gazebo/src/robot_models/marco/hit_gripper/hit_gripper_description/meshes/gear.stl</uri>
            </mesh>
          </geometry>
          <material>
            <script>
              <name>Gazebo/White</name>
              <uri>file://media/materials/scripts/gazebo.material</uri>
            </script>
          </material>
        </visual>
        <gravity>1</gravity>
        <velocity_decay/>
        <self_collide>0</self_collide>
        <kinematic>0</kinematic>
      </link>
      <joint name='gripper_joint' type='revolute'>
        <child>gripper_link</child>
        <parent>arm_7_link</parent>
        <axis>
          <xyz>0 0 1</xyz>
          <limit>
            <lower>-0.226893</lower>
            <upper>1.0472</upper>
            <effort>1</effort>
            <velocity>1</velocity>
          </limit>
          <dynamics>
            <damping>1</damping>
            <friction>1</friction>
            <spring_reference>0</spring_reference>
            <spring_stiffness>0</spring_stiffness>
          </dynamics>
          <use_parent_model_frame>1</use_parent_model_frame>
        </axis>
        <physics>
          <provide_feedback>1</provide_feedback>
          <ode>
            <provide_feedback>1</provide_feedback>
            <implicit_spring_damper>1</implicit_spring_damper>
            <cfm_damping>1</cfm_damping>
            <limit>
              <cfm>0</cfm>
              <erp>0.2</erp>
            </limit>
          </ode>
        </physics>
      </joint>
      <link name='head_1_link'>
        <pose frame=''>0.125 0 0.8978 0 -0 0</pose>
        <inertial>
          <pose frame=''>0.0208 -0.00025 0.0215 0 -0 0</pose>
          <mass>0.09793</mass>
          <inertia>
            <ixx>5.84463e-05</ixx>
            <ixy>-5.1494e-07</ixy>
            <ixz>4.66297e-05</ixz>
            <iyy>1.16144e-05</iyy>
            <iyz>1e-09</iyz>
            <izz>5.23659e-05</izz>
          </inertia>
        </inertial>
        <collision name='head_1_link_collision'>
          <pose frame=''>0.0305 0 0.0175 0 -0 0</pose>
          <geometry>
            <box>
              <size>0.05 0.035 0.035</size>
            </box>
          </geometry>
          <surface>
            <contact>
              <ode/>
            </contact>
            <friction>
              <ode>
                <mu>0.9</mu>
                <mu2>0.9</mu2>
              </ode>
              <torsional>
                <ode/>
              </torsional>
            </friction>
            <bounce/>
          </surface>
          <max_contacts>10</max_contacts>
        </collision>
        <visual name='head_1_link_visual'>
          <pose frame=''>0.0305 0 0.0175 0 -0 0</pose>
          <geometry>
            <box>
              <size>0.05 0.035 0.035</size>
            </box>
          </geometry>
          <material>
            <script>
              <uri>__default__</uri>
              <name>__default__</name>
            </script>
          </material>
        </visual>
        <gravity>1</gravity>
        <velocity_decay/>
        <self_collide>0</self_collide>
        <kinematic>0</kinematic>
      </link>
      <joint name='head_1_joint' type='revolute'>
        <child>head_1_link</child>
        <parent>torso_lift_link</parent>
        <axis>
          <xyz>0 0 1</xyz>
          <limit>
            <lower>-1.309</lower>
            <upper>1.309</upper>
            <effort>5.197</effort>
            <velocity>3</velocity>
          </limit>
          <dynamics>
            <damping>0.5</damping>
            <friction>1</friction>
            <spring_reference>0</spring_reference>
            <spring_stiffness>0</spring_stiffness>
          </dynamics>
          <use_parent_model_frame>1</use_parent_model_frame>
        </axis>
        <physics>
          <ode>
            <implicit_spring_damper>1</implicit_spring_damper>
            <cfm_damping>1</cfm_damping>
            <limit>
              <cfm>0</cfm>
              <erp>0.2</erp>
            </limit>
          </ode>
        </physics>
      </joint>
      <link name='head_2_link'>
        <pose frame=''>0.1605 0 0.9208 1.5708 -0 0</pose>
        <inertial>
          <pose frame=''>0.047921 0.000678 0.000239 0 -0 0</pose>
          <mass>0.47345</mass>
          <inertia>
            <ixx>0.000197179</ixx>
            <ixy>-4.35389e-05</ixy>
            <ixz>3.86464e-06</ixz>
            <iyy>0.000531591</iyy>
            <iyz>5.51713e-06</iyz>
            <izz>0.000640406</izz>
          </inertia>
        </inertial>
        <collision name='head_2_link_collision'>
          <pose frame=''>0.05 0 0 1.5708 -0 0</pose>
          <geometry>
            <box>
              <size>0.05 0.21 0.085</size>
            </box>
          </geometry>
          <surface>
            <contact>
              <ode/>
            </contact>
            <friction>
              <ode>
                <mu>0.9</mu>
                <mu2>0.9</mu2>
              </ode>
              <torsional>
                <ode/>
              </torsional>
            </friction>
            <bounce/>
          </surface>
          <max_contacts>10</max_contacts>
        </collision>
        <collision name='head_2_link_fixed_joint_lump__xtion_link_collision_1'>
          <pose frame=''>0.054192 0.017614 -0.0025 -1.5708 0 0</pose>
          <geometry>
            <box>
              <size>0.04 0.185 0.03</size>
            </box>
          </geometry>
          <surface>
            <contact>
              <ode/>
            </contact>
            <friction>
              <ode/>
              <torsional>
                <ode/>
              </torsional>
            </friction>
            <bounce/>
          </surface>
          <max_contacts>10</max_contacts>
        </collision>
        <visual name='head_2_link_visual'>
          <pose frame=''>0.070192 0.017614 0 3.14159 1.57079 3.14159</pose>
          <geometry>
            <mesh>
              <scale>1 1 1</scale>
              <uri>/home/jasper/omni_marco_gazebo/src/robot_models/marco/marco_description/meshes/head.dae</uri>
            </mesh>
          </geometry>
          <material>
            <script>
              <uri>__default__</uri>
              <name>__default__</name>
            </script>
          </material>
        </visual>
        <visual name='head_2_link_fixed_joint_lump__xtion_link_visual_1'>
          <pose frame=''>0.064192 0.017614 0 -1.5708 0 0</pose>
          <geometry>
            <mesh>
              <scale>1 1 1</scale>
              <uri>/home/jasper/omni_marco_gazebo/src/robot_models/marco/marco_description/meshes/sensors/xtion_pro_live/xtion_pro_live.dae</uri>
            </mesh>
          </geometry>
          <material>
            <script>
              <uri>__default__</uri>
              <name>__default__</name>
            </script>
          </material>
        </visual>
        <velocity_decay/>
        <gravity>1</gravity>
        <velocity_decay/>
        <self_collide>0</self_collide>
        <sensor name='xtion_frame_sensor' type='depth'>
          <always_on>1</always_on>
          <update_rate>30</update_rate>
          <camera name='__default__'>
            <horizontal_fov>1.01229</horizontal_fov>
            <image>
              <format>R8G8B8</format>
              <width>640</width>
              <height>480</height>
            </image>
            <clip>
              <near>0.3</near>
              <far>8</far>
            </clip>
          </camera>
          <plugin name='xtion_frame_controller' filename='libgazebo_ros_openni_kinect.so'>
            <alwaysOn>true</alwaysOn>
            <updateRate>30.0</updateRate>
            <cameraName>xtion</cameraName>
            <imageTopicName>ir/image_raw</imageTopicName>
            <cameraInfoTopicName>/ir/camera_info</cameraInfoTopicName>
            <depthImageTopicName>depth/image_raw</depthImageTopicName>
            <depthImageCameraInfoTopicName>depth/camera_info</depthImageCameraInfoTopicName>
            <pointCloudTopicName>depth/points</pointCloudTopicName>
            <frameName>xtion_optical_frame</frameName>
            <pointCloudCutoff>0.5</pointCloudCutoff>
            <distortionK1>0.00000001</distortionK1>
            <distortionK2>0.00000001</distortionK2>
            <distortionK3>0.00000001</distortionK3>
            <distortionT1>0.00000001</distortionT1>
            <distortionT2>0.00000001</distortionT2>
            <robotNamespace>/</robotNamespace>
          </plugin>
          <pose frame=''>0.064192 0.017614 0 -1.5708 0 0</pose>
        </sensor>
        <sensor name='xtion_frame_sensor' type='depth'>
          <always_on>1</always_on>
          <update_rate>20</update_rate>
          <camera name='__default__'>
            <horizontal_fov>0.994838</horizontal_fov>
            <image>
              <format>R8G8B8</format>
              <width>640</width>
              <height>480</height>
            </image>
            <clip>
              <near>0.01</near>
              <far>5</far>
            </clip>
          </camera>
          <plugin name='xtion_frame_controller' filename='libgazebo_ros_openni_kinect.so'>
            <alwaysOn>true</alwaysOn>
            <updateRate>30.0</updateRate>
            <cameraName>xtion</cameraName>
            <imageTopicName>rgb/image_raw</imageTopicName>
            <cameraInfoTopicName>rgb/camera_info</cameraInfoTopicName>
            <depthImageTopicName>depth_registered/image_raw</depthImageTopicName>
            <depthImageCameraInfoTopicName>depth_registered/camera_info</depthImageCameraInfoTopicName>
            <pointCloudTopicName>depth_registered/points</pointCloudTopicName>
            <frameName>xtion_rgb_optical_frame</frameName>
            <pointCloudCutoff>0.5</pointCloudCutoff>
            <pointCloudCutoffMax>8.0</pointCloudCutoffMax>
            <distortionK1>0.00000001</distortionK1>
            <distortionK2>0.00000001</distortionK2>
            <distortionK3>0.00000001</distortionK3>
            <distortionT1>0.00000001</distortionT1>
            <distortionT2>0.00000001</distortionT2>
            <robotNamespace>/</robotNamespace>
          </plugin>
          <pose frame=''>0.064192 0.017614 0 -1.5708 0 0</pose>
        </sensor>
        <kinematic>0</kinematic>
      </link>
      <joint name='head_2_joint' type='revolute'>
        <child>head_2_link</child>
        <parent>head_1_link</parent>
        <axis>
          <xyz>0 -1 0</xyz>
          <limit>
            <lower>-1.0472</lower>
            <upper>0.632682</upper>
            <effort>2.77</effort>
            <velocity>3</velocity>
          </limit>
          <dynamics>
            <damping>0.5</damping>
            <friction>1</friction>
            <spring_reference>0</spring_reference>
            <spring_stiffness>0</spring_stiffness>
          </dynamics>
          <use_parent_model_frame>1</use_parent_model_frame>
        </axis>
        <physics>
          <ode>
            <implicit_spring_damper>1</implicit_spring_damper>
            <cfm_damping>1</cfm_damping>
            <limit>
              <cfm>0</cfm>
              <erp>0.2</erp>
            </limit>
          </ode>
        </physics>
      </joint>
      <link name='wheel_left_link'>
        <pose frame=''>0 0.2022 0.0985 -1.5708 0 0</pose>
        <inertial>
          <pose frame=''>0 0 0.00207 0 -0 0</pose>
          <mass>1.82362</mass>
          <inertia>
            <ixx>0.00499743</ixx>
            <ixy>-4.464e-08</ixy>
            <ixz>-2.245e-08</ixz>
            <iyy>0.00499742</iyy>
            <iyz>1.64e-09</iyz>
            <izz>0.0083924</izz>
          </inertia>
        </inertial>
        <collision name='wheel_left_link_collision'>
          <pose frame=''>0 0 0 0 -0 0</pose>
          <geometry>
            <cylinder>
              <length>0.04</length>
              <radius>0.0985</radius>
            </cylinder>
          </geometry>
          <surface>
            <contact>
              <ode>
                <kp>1e+06</kp>
                <kd>100</kd>
                <max_vel>1</max_vel>
                <min_depth>0.003</min_depth>
              </ode>
            </contact>
            <friction>
              <ode>
                <mu>1</mu>
                <mu2>1</mu2>
                <fdir1>1 0 0</fdir1>
              </ode>
              <torsional>
                <ode/>
              </torsional>
            </friction>
            <bounce/>
          </surface>
          <max_contacts>10</max_contacts>
        </collision>
        <visual name='wheel_left_link_visual'>
          <pose frame=''>0 0 0 3.14159 -0 0</pose>
          <geometry>
            <mesh>
              <scale>1 1 1</scale>
              <uri>/home/jasper/omni_marco_gazebo/src/robot_models/marco/ant_description/meshes/wheels/wheel.stl</uri>
            </mesh>
          </geometry>
          <material>
            <script>
              <name>Gazebo/DarkGrey</name>
              <uri>file://media/materials/scripts/gazebo.material</uri>
            </script>
          </material>
        </visual>
        <gravity>1</gravity>
        <velocity_decay/>
        <self_collide>0</self_collide>
        <kinematic>0</kinematic>
      </link>
      <joint name='wheel_left_joint' type='revolute'>
        <child>wheel_left_link</child>
        <parent>base_footprint</parent>
        <axis>
          <xyz>0 1 0</xyz>
          <limit>
            <lower>-1e+16</lower>
            <upper>1e+16</upper>
          </limit>
          <dynamics>
            <spring_reference>0</spring_reference>
            <spring_stiffness>0</spring_stiffness>
          </dynamics>
          <use_parent_model_frame>1</use_parent_model_frame>
        </axis>
      </joint>
      <link name='wheel_right_link'>
        <pose frame=''>0 -0.2022 0.0985 -1.5708 0 0</pose>
        <inertial>
          <pose frame=''>0 0 -0.00207 0 -0 0</pose>
          <mass>1.82362</mass>
          <inertia>
            <ixx>0.00499743</ixx>
            <ixy>4.464e-08</ixy>
            <ixz>-2.245e-08</ixz>
            <iyy>0.00499742</iyy>
            <iyz>-1.64e-09</iyz>
            <izz>0.0083924</izz>
          </inertia>
        </inertial>
        <collision name='wheel_right_link_collision'>
          <pose frame=''>0 0 0 0 -0 0</pose>
          <geometry>
            <cylinder>
              <length>0.04</length>
              <radius>0.0985</radius>
            </cylinder>
          </geometry>
          <surface>
            <contact>
              <ode>
                <kp>1e+06</kp>
                <kd>100</kd>
                <max_vel>1</max_vel>
                <min_depth>0.003</min_depth>
              </ode>
            </contact>
            <friction>
              <ode>
                <mu>1</mu>
                <mu2>1</mu2>
                <fdir1>1 0 0</fdir1>
              </ode>
              <torsional>
                <ode/>
              </torsional>
            </friction>
            <bounce/>
          </surface>
          <max_contacts>10</max_contacts>
        </collision>
        <visual name='wheel_right_link_visual'>
          <pose frame=''>0 0 0 0 -0 0</pose>
          <geometry>
            <mesh>
              <scale>1 1 1</scale>
              <uri>/home/jasper/omni_marco_gazebo/src/robot_models/marco/ant_description/meshes/wheels/wheel.stl</uri>
            </mesh>
          </geometry>
          <material>
            <script>
              <name>Gazebo/DarkGrey</name>
              <uri>file://media/materials/scripts/gazebo.material</uri>
            </script>
          </material>
        </visual>
        <gravity>1</gravity>
        <velocity_decay/>
        <self_collide>0</self_collide>
        <kinematic>0</kinematic>
      </link>
      <joint name='wheel_right_joint' type='revolute'>
        <child>wheel_right_link</child>
        <parent>base_footprint</parent>
        <axis>
          <xyz>0 1 0</xyz>
          <limit>
            <lower>-1e+16</lower>
            <upper>1e+16</upper>
          </limit>
          <dynamics>
            <spring_reference>0</spring_reference>
            <spring_stiffness>0</spring_stiffness>
          </dynamics>
          <use_parent_model_frame>1</use_parent_model_frame>
        </axis>
      </joint>
      <plugin name='gazebo_ros_control' filename='libgazebo_ros_control.so'>
        <ns/>
        <robotSimType>pal_hardware_gazebo/PalHardwareGazebo</robotSimType>
        <robotNamespace/>
        <controlPeriod>0.001</controlPeriod>
      </plugin>
      <plugin name='gazebo_ros_p3d' filename='libgazebo_ros_p3d.so'>
        <topicName>ground_truth_odom</topicName>
        <alwaysOn>true</alwaysOn>
        <updateRate>100.0</updateRate>
        <robotNamespace>/</robotNamespace>
        <bodyName>base_footprint</bodyName>
        <xyzOffset>0 0 -0.0985</xyzOffset>
        <rpyOffset>0 -0 0</rpyOffset>
      </plugin>
      <plugin name='gazebo_ros_odometry' filename='libgazebo_world_odometry.so'>
        <frameName>base_footprint</frameName>
        <topicName>floating_base_pose_simulated</topicName>
        <robotNamespace>/</robotNamespace>
      </plugin>
      <static>0</static>
      <plugin name='mimic_gripper_finger_inner_left_joint' filename='libroboticsgroup_gazebo_mimic_joint_plugin.so'>
        <joint>gripper_joint</joint>
        <mimicJoint>gripper_finger_inner_left_joint</mimicJoint>
        <multiplier>1.0</multiplier>
        <offset>0.0</offset>
        <robotNamespace>/</robotNamespace>
      </plugin>
      <plugin name='mimic_gripper_finger_inner_right_joint' filename='libroboticsgroup_gazebo_mimic_joint_plugin.so'>
        <joint>gripper_joint</joint>
        <mimicJoint>gripper_finger_inner_right_joint</mimicJoint>
        <multiplier>-1.0</multiplier>
        <offset>0.0</offset>
        <robotNamespace>/</robotNamespace>
      </plugin>
      <plugin name='mimic_gripper_finger_outer_left_joint' filename='libroboticsgroup_gazebo_mimic_joint_plugin.so'>
        <joint>gripper_joint</joint>
        <mimicJoint>gripper_finger_outer_left_joint</mimicJoint>
        <multiplier>1.0</multiplier>
        <offset>0.0</offset>
        <robotNamespace>/</robotNamespace>
      </plugin>
      <plugin name='mimic_gripper_finger_outer_right_joint' filename='libroboticsgroup_gazebo_mimic_joint_plugin.so'>
        <joint>gripper_joint</joint>
        <mimicJoint>gripper_finger_outer_right_joint</mimicJoint>
        <multiplier>1.0</multiplier>
        <offset>0.0</offset>
        <robotNamespace>/</robotNamespace>
      </plugin>
      <plugin name='mimic_gripper_finger_tip_left_joint' filename='libroboticsgroup_gazebo_mimic_joint_plugin.so'>
        <joint>gripper_joint</joint>
        <mimicJoint>gripper_finger_tip_left_joint</mimicJoint>
        <multiplier>1.0</multiplier>
        <offset>0.0</offset>
        <robotNamespace>/</robotNamespace>
      </plugin>
      <plugin name='mimic_gripper_finger_tip_right_joint' filename='libroboticsgroup_gazebo_mimic_joint_plugin.so'>
        <joint>gripper_joint</joint>
        <mimicJoint>gripper_finger_tip_right_joint</mimicJoint>
        <multiplier>1.0</multiplier>
        <offset>0.0</offset>
        <robotNamespace>/</robotNamespace>
      </plugin>
      <pose frame=''>0 0 0.001 0 -0 0</pose>
    </model>
  </world>
</sdf>
