<sdf version='1.6'>
  <model name='microwave_oven'>
    <link name='base_link'>
      <pose frame=''>0 0 0 0 -0 0</pose>
      <inertial>
        <pose frame=''>-0.003499 0.0063 0.095793 0 -0 0</pose>
        <mass>10.69</mass>
        <inertia>
          <ixx>0.15798</ixx>
          <ixy>0.002699</ixy>
          <ixz>0.0025714</ixz>
          <iyy>0.31998</iyy>
          <iyz>-0.0019679</iyz>
          <izz>0.30475</izz>
        </inertia>
      </inertial>
      <collision name='base_link_collision'>
        <pose frame=''>0 0 0 0 -0 0</pose>
        <geometry>
          <mesh>
            <scale>1 1 1</scale>
            <uri>model://microwave_oven/meshes/base_link.STL</uri>
          </mesh>
        </geometry>
      </collision>
      <visual name='base_link_visual'>
        <pose frame=''>0 0 0 0 -0 0</pose>
        <geometry>
          <mesh>
            <scale>1 1 1</scale>
            <uri>model://microwave_oven/meshes/base_link.STL</uri>
          </mesh>
        </geometry>
      </visual>
    </link>
    <link name='door_link'>
      <pose frame=''>-0.2115 -0.13648 0.002131 1.5708 -0 0</pose>
      <inertial>
        <pose frame=''>0.18216 0.11795 0.017746 0 -0 0</pose>
        <mass>1.117</mass>
        <inertia>
          <ixx>0.0067183</ixx>
          <ixy>-1.793e-07</ixy>
          <ixz>-0.00018641</ixz>
          <iyy>0.015795</iyy>
          <iyz>-8.4864e-08</iyz>
          <izz>0.022237</izz>
        </inertia>
      </inertial>
      <collision name='door_link_collision'>
        <pose frame=''>0 0 0 0 -0 0</pose>
        <geometry>
          <mesh>
            <scale>1 1 1</scale>
            <uri>model://microwave_oven/meshes/door_link.STL</uri>
          </mesh>
        </geometry>
      </collision>
      <visual name='door_link_visual'>
        <pose frame=''>0 0 0 0 -0 0</pose>
        <geometry>
          <mesh>
            <scale>1 1 1</scale>
            <uri>model://microwave_oven/meshes/door_link.STL</uri>
          </mesh>
        </geometry>
      </visual>
    </link>
    <joint name='door_joint' type='revolute'>
      <child>door_link</child>
      <parent>base_link</parent>
      <axis>
        <xyz>0 0 1</xyz>
        <limit>
          <lower>-1.5708</lower>
          <upper>0</upper>
          <effort>30</effort>
          <velocity>1.0</velocity>
        </limit>
        <dynamics>
          <damping>0.5</damping>
          <friction>5</friction>
          <spring_reference>0</spring_reference>
          <spring_stiffness>0</spring_stiffness>
        </dynamics>
        <use_parent_model_frame>1</use_parent_model_frame>
      </axis>
    </joint>
  </model>
</sdf>
