<?xml version="1.0" encoding="utf-8"?>
<!-- This URDF was automatically created by SolidWorks to URDF Exporter! Originally created by Stephen Brawner (brawner@gmail.com) 
     Commit Version: 1.5.1-0-g916b5db  Build Version: 1.5.7152.31018
     For more information, please see http://wiki.ros.org/sw_urdf_exporter -->
<robot
  name="microwave_oven">
  <link
    name="base_link">
    <inertial>
      <origin
        xyz="-0.0034987 0.0062999 0.095793"
        rpy="0 0 0" />
      <mass
        value="10.69" />
      <inertia
        ixx="0.15798"
        ixy="0.002699"
        ixz="0.0025714"
        iyy="0.31998"
        iyz="-0.0019679"
        izz="0.30475" />
    </inertial>
    <visual>
      <origin
        xyz="0 0 0"
        rpy="0 0 0" />
      <geometry>
        <mesh
          filename="package://microwave_oven/meshes/base_link.STL" />
      </geometry>
      <material
        name="">
        <color
          rgba="0.77647 0.75686 0.73725 1" />
      </material>
    </visual>
    <collision>
      <origin
        xyz="0 0 0"
        rpy="0 0 0" />
      <geometry>
        <mesh
          filename="package://microwave_oven/meshes/base_link.STL" />
      </geometry>
    </collision>
  </link>
  <link
    name="door_link">
    <inertial>
      <origin
        xyz="0.18216 0.11795 0.017746"
        rpy="0 0 0" />
      <mass
        value="1.117" />
      <inertia
        ixx="0.0067183"
        ixy="-1.793E-07"
        ixz="-0.00018641"
        iyy="0.015795"
        iyz="-8.4864E-08"
        izz="0.022237" />
    </inertial>
    <visual>
      <origin
        xyz="0 0 0"
        rpy="0 0 0" />
      <geometry>
        <mesh
          filename="package://microwave_oven/meshes/door_link.STL" />
      </geometry>
      <material
        name="">
        <color
          rgba="0 0 0 1" />
      </material>
    </visual>
    <collision>
      <origin
        xyz="0 0 0"
        rpy="0 0 0" />
      <geometry>
        <mesh
          filename="package://microwave_oven/meshes/door_link.STL" />
      </geometry>
    </collision>
  </link>
  <joint
    name="door_joint"
    type="revolute">
    <origin
      xyz="-0.2115 -0.13648 0.0021306"
      rpy="1.5708 0 0" />
    <parent
      link="base_link" />
    <child
      link="door_link" />
    <axis
      xyz="0 1 0" />
    <limit
      lower="-1.5708"
      upper="0"
      effort="0"
      velocity="0" />
  </joint>
</robot>